Workbook
Name CorrectiveMajor: CorrectiveMajor!$A$3:$A$500
Name CorrectiveMinor: CorrectiveMinor!$A$3:$A$500
Name inputs_dedicated_vessel_cost: C_inputs!#REF!
Name inputs_distance: TSA_inputs!$C$7
Name inputs_export_length: TSA_inputs!$C$11
Name inputs_fail_ratio: SA_inputs!$C$11
Name inputs_infant: SA_inputs!$C$9
Name inputs_lat: TSA_inputs!$C$2
Name inputs_lifetime: SA_inputs!$C$2
Name inputs_lon: TSA_inputs!$C$3
Name inputs_max_wow: TSA_inputs!$C$9
Name inputs_metocean_file: TSA_inputs!$C$4
Name inputs_montecarlo: TSA_inputs!$C$10
Name inputs_port_costs_day: SA_inputs!#REF!
Name inputs_port_costs_year: C_inputs!$C$5
Name inputs_roughness: TSA_inputs!$C$6
Name inputs_shift_dur: TSA_inputs!$C$12
Name inputs_speed_height: TSA_inputs!$C$5
Name inputs_surface_roughness: TSA_inputs!$C$6
Name inputs_terminal_daily_cost: C_inputs!$C$5
Name inputs_transit_between_devices: TSA_inputs!$C$8
Name inputs_wearout: SA_inputs!$C$10
Name pv_devices: Gen_PV!$C$3
Name pv_islands: Gen_PV!$C$2
Name pv_power: Gen_PV!$C$7
Name pv_power_file: Gen_PV!$C$8
Name Tow: OperationTow!$A$3:$A$500
Name wec_devices: Gen_WEC!$C$2
Name wec_power: Gen_WEC!$C$3
Name wec_power_file: Gen_WEC!$C$4
Name wtg_cutin: Gen_WTG!$C$4
Name wtg_cutoff: Gen_WTG!$C$5
Name wtg_devices: Gen_WTG!$C$2
Name wtg_moorings: Gen_WTG!$C$8
Name wtg_power: Gen_WTG!$C$3
Name wtg_power_file: Gen_WTG!$C$7

Sheet Front_page
C2: Experienced users only
B3: Gen | C3: General
B4: TSA | C4: Timeseries analysis
B5: SA | C5: Statistical analysis
B6: C | C6: Cost analysis

Sheet Gen_inputs
A1: input | B1: units | C1: value
A2: Use previous run directory | B2: -
A3: Use previous TimeSeries Analysis | B3: - | C3: FALSE
A4: Number of runs with same TimeSeries Analysis | B4: - | C4: 10
A5: Overwrite run directory | B5: -
A6: Consider double shifts | B6: -
A7: Log events file | B7: -
A8: Failure events file | B8: -
A9: Power events file | B9: -

Sheet Gen_WTG
A1: Input | B1: Units | C1: Value
A2: WTG devices | B2: - | C2: 0
A3: WTG rated power | B3: MW/device
A4: WTG cut-in wind speed | B4: m/s
A5: WTG cut-off wind speed | B5: m/s
A6: WTG hub height | B6: m
A7: WTG power curve file | B7: -
A8: Moorings per WTG | B8: -
A9: WTG number of strings | B9: -
A10: WTG n strings to connector | B10: -
A11: WTG type layout | B11: -
A12: WTG number of substations | B12: -
A13: WTG number of export cables | B13: -
A14: Tow string shutdown | B14: -
... A17: WTG distances | B17: km

Sheet Gen_WEC
A1: Input | B1: Units | C1: Value
A2: WEC devices | B2: - | C2: 1
A3: WEC rated power | B3: kW/device | C3: 400
A4: WEC power matrix file | B4: - | C4: .\tests\test_files\pmatrix_wave.csv
A5: WEC number of strings | B5: - | C5: 1
A6: WEC n strings to connector | B6: -
A7: WEC type layout | B7: - | C7: 5
A8: WEC number of substations | B8: - | C8: 1
A9: WEC number of export cables | B9: - | C9: 1
A10: WEC number of O&M device at port | B10: - | C10: 1
A11: WEC number of device stored at port | B11: - | C11: 0
A12: Tow string shutdown | B12: -
A13: WEC distances | B13: km

Sheet Gen_PV
A1: Input | B1: Units | C1: Value
A2: PV inverters | B2: -
A3: PV devices | B3: -
A4: PV strings | B4: -
A5: PV MV transformers | B5: -
A6: PV rated device power | B6: kW/device
A7: Morings | B7: -
A8: Anchors
A9: Floaters | B9: -
A10: PV power curve file | B10: -
A11: Degradation rate | B11: %/year
A12: PV layout | B12: -
A13: PV number of substations | B13: -
A14: max failure module each str | B14: -
A15: PV number of export cables | B15: -
A16: PV number island per array | B16: -
A17: PV number of O&M device at port | B17: -
A18: PV number of device stored at port | B18: -
A19: Tow string shutdown | B19: -
A20: PV distances | B20: km

Sheet Gen_Vessels
A1: id | B1: type | C1: list_name | D1: number_vessels | E1: speed_transit | F1: speed_towing | G1: daily_charter | H1: mobilisation_time | I1: mobilisation_cost | J1: crew_capacity | K1: num_berths | L1: power | M1: fuel_type | N1: overnight | O1: mother_vessel | P1: fuel_cons_transit | Q1: fuel_cons_maneuver | R1: fuel_cons_standby | S1: annual_contract | T1: n_ves_annual_contract | U1: months_contract | V1: monthly_contract_cost | W1: n_ves_monthly_contract | X1: notes
A2: - | E2: m/s | F2: m/s | G2: € | H2: h | I2: € | J2: - | K2: - | L2: kW | M2: - | N2: - | O2: - | P2: l/h | Q2: l/h | R2: l/h | S2: €/year | T2: - | U2: - | V2: €/month | W2: -
A3: V001 | B3: Tug | C3: =_xlfn.CONCAT(A3," - ",B3) -> V001 - Tug | D3: 2 | E3: 3 | F3: 2 | G3: 2500 | H3: 0 | I3: 0 | J3: 2 | L3: 600 | N3: FALSE | O3: FALSE
A4: V002 | B4: Multicat | C4: =_xlfn.CONCAT(A4," - ",B4) -> V002 - Multicat | D4: 1 | E4: 4 | F4: 2 | G4: 3000 | H4: 0 | I4: 0 | J4: 6 | L4: 350 | N4: FALSE | O4: FALSE | P4: 0.35 | Q4: 0.22 | R4: 0.1
A5: V003 | B5: AHTS | C5: =_xlfn.CONCAT(A5," - ",B5) -> V003 - AHTS | D5: 1 | E5: 5 | F5: 2 | G5: 4500 | H5: 0 | I5: 0 | J5: 2 | L5: 750 | N5: FALSE | O5: FALSE
A6: V004 | B6: DSV | C6: =_xlfn.CONCAT(A6," - ",B6) -> V004 - DSV | D6: 1 | E6: 4 | G6: 3500 | H6: 72 | I6: 10000 | J6: 12 | L6: 250 | N6: FALSE | O6: FALSE | P6: 0.32 | Q6: 0.12 | R6: 0.05
A7: V005 | B7: CTV | C7: =_xlfn.CONCAT(A7," - ",B7) -> V005 - CTV | D7: 2 | E7: 8 | G7: 2200 | H7: 0 | I7: 0 | J7: 12 | L7: 200 | M7: MDO | N7: FALSE | O7: FALSE | P7: 0.4 | Q7: 0.05 | R7: 0.01
A8: V006 | B8: Multicat | C8: =_xlfn.CONCAT(A8," - ",B8) -> V006 - Multicat | D8: 1 | E8: 12 | F8: 2 | G8: 5600 | H8: 168 | I8: 1000 | J8: 6 | L8: 4046 | M8: MDO | N8: FALSE | O8: FALSE | X8: CPO vessel
A9: V101 | B9: CTV | C9: =_xlfn.CONCAT(A9," - ",B9) -> V101 - CTV | D9: 2 | E9: 12 | G9: 0 | H9: 24 | I9: 500 | J9: 6 | L9: 200 | M9: MDO | N9: FALSE | O9: FALSE | S9: 900000 | T9: 2 | X9: Farm dedicated vessel 1
A10: V201 | B10: CTV | C10: =_xlfn.CONCAT(A10," - ",B10) -> V201 - CTV | D10: 3 | E10: 10.3 | G10: 3800 | H10: 24 | I10: 500 | J10: 12 | L10: 1500 | M10: MDO | N10: FALSE | O10: FALSE

Sheet Gen_ROVs
A1: id | B1: rov name | C1: type | E1: dimensions | F1: weight | G1: useful_capacity | H1: speed_transit | I1: battery_capacity | J1: recharging_duration | K1: max_distance | L1: avg_autonomy | M1: on_site | N1: support_vessel | O1: nr_technicians | P1: ws_max | Q1: h_max | R1: hs_max | S1: daylight | T1: precipitation_max | U1: cost_half_day | V1: daily_charter
A2: [-] | B2: [-] | C2: [-] | E2: [m] | F2: [kg] | G2: [kg] | H2: [km/h] | I2: [kWh] | J2: [h] | K2: [km] | L2: [h] | M2: [-] | N2: [-] | O2: [-] | P2: [m/s] | Q2: [m] | R2: [m] | S2: [-] | T2: [mm]
A3: stork_1 | B3: Stork | C3: Aerial | D3: =A3&" - "&B3&" ("&C3&")" -> stork_1 - Stork (Aerial) | E3: 1.5 | G3: 5 | H3: 17 | J3: 3 | K3: =H3*L3 -> 10.2 | L3: 0.6 | M3: TRUE | N3: CTV | O3: 1 | P3: 10 | V3: 4920
A4: grifo_1 | B4: Grifo | C4: Aerial | D4: =A4&" - "&B4&" ("&C4&")" -> grifo_1 - Grifo (Aerial) | H4: 17 | J4: 3 | L4: 0.5 | M4: TRUE | N4: CTV | O4: 2 | P4: 10 | U4: 7540 | V4: 4920
A5: EVA_AUV_1 | B5: EVA_AUV | C5: Water | D5: =A5&" - "&B5&" ("&C5&")" -> EVA_AUV_1 - EVA_AUV (Water) | E5: 0.9 | F5: 290 | M5: FALSE | N5: CTV | O5: 2 | U5: 9700 | V5: 6000
A6: EVA_ROV_2 | B6: EVA_ROV | C6: Water | D6: =A6&" - "&B6&" ("&C6&")" -> EVA_ROV_2 - EVA_ROV (Water) | E6: 1.8 | F6: 2540 | M6: FALSE | N6: DSV | O6: 3 | U6: 13300 | V6: 7800
A7: IRIS_AUV | B7: IRIS_AUV | C7: Water | D7: =A7&" - "&B7&" ("&C7&")" -> IRIS_AUV - IRIS_AUV (Water) | V7: 7800
A8: IRIS_ROV | B8: IRIS_ROV | C8: Water | D8: =A8&" - "&B8&" ("&C8&")" -> IRIS_ROV - IRIS_ROV (Water) | V8: 7800
D9: =A9&" - "&B9&" ("&C9&")" -> - ()
D10: =A10&" - "&B10&" ("&C10&")" -> - ()
D11: =A11&" - "&B11&" ("&C11&")" -> - ()
D12: =A12&" - "&B12&" ("&C12&")" -> - ()
D13: =A13&" - "&B13&" ("&C13&")" -> - ()
D14: =A14&" - "&B14&" ("&C14&")" -> - ()
D15: =A15&" - "&B15&" ("&C15&")" -> - ()
D16: =A16&" - "&B16&" ("&C16&")" -> - ()
D17: =A17&" - "&B17&" ("&C17&")" -> - ()
D18: =A18&" - "&B18&" ("&C18&")" -> - ()
D19: =A19&" - "&B19&" ("&C19&")" -> - ()
D20: =A20&" - "&B20&" ("&C20&")" -> - ()
... D63: =A63&" - "&B63&" ("&C63&")" -> - ()

Sheet InspectionSite
A1: id | B1: id_short | C1: name | D1: overnight_stay | E1: periodicity | F1: preferred_months | G1: day_start | H1: wtg_intervened | I1: wec_intervened | J1: pv_intervened | K1: dur_per_device | L1: device_shutdown | M1: hs | N1: tp | O1: ws | P1: ws_hub | Q1: cs | R1: light | S1: vessel1 | T1: vessel1_id | U1: vessel1_qt | V1: vessel2 | W1: vessel2_id | X1: vessel2_qt | Y1: rov_drone | Z1: technicians_per_device | AA1: technician_cost | AB1: parts_cost | AC1: other_costs | AD1: level | AE1: to_group_with | AF1: to_be_grouped | AG1: double_shift
A2: - | B2: - | C2: - | D2: - | E2: every X years | F2: - | G2: - | H2: - | I2: - | J2: - | K2: h | L2: - | M2: m | N2: s | O2: m/s | P2: m/s | Q2: m/s | R2: - | S2: - | T2: - | U2: - | V2: - | W2: - | X2: - | Y2: - | Z2: - | AA2: €/technician/day | AB2: € | AC2: € | AD2: - | AE2: - | AF2: - | AG2: -
A3: =IF(ISBLANK($B3)=FALSE,IF(AND($H3>0,$I3<=0,$J3<=0),_xlfn.CONCAT("ofw_",$B3),IF(AND($H3<=0,$I3>0,$J3<=0),_xlfn.CONCAT("owc_",$B3),IF(AND($H3<=0,$I3<=0,$J3>0),_xlfn.CONCAT("opv_",$B3),_xlfn.CONCAT("oce_",$B3)))),"") -> owc_CPO_A1 | B3: CPO_A1 | C3: Power Electronics inspection | D3: FALSE | E3: 1 | F3: 7 | H3: 0 | I3: =wec_devices -> 1 | J3: 0 | K3: 1 | L3: TRUE | M3: 1.5 | R3: TRUE | S3: V201 - CTV | T3: =IFERROR(IF(ISBLANK(S3),"",INDEX(Gen_Vessels!$A$3:$C$500,MATCH(InspectionSite!$S3,Gen_Vessels!$C$3:$C$500,0),1)),"") -> V201 | U3: 1 | W3: =IFERROR(IF(ISBLANK(V3),"",INDEX(Gen_Vessels!$A$3:$C$500,MATCH(InspectionSite!$V3,Gen_Vessels!$C$3:$C$500,0),1)),"") | Z3: 2 | AD3: device
A4: =IF(ISBLANK($B4)=FALSE,IF(AND($H4>0,$I4<=0,$J4<=0),_xlfn.CONCAT("ofw_",$B4),IF(AND($H4<=0,$I4>0,$J4<=0),_xlfn.CONCAT("owc_",$B4),IF(AND($H4<=0,$I4<=0,$J4>0),_xlfn.CONCAT("opv_",$B4),_xlfn.CONCAT("oce_",$B4)))),"") -> owc_CPO_A2 | B4: CPO_A2 | C4: C-GEN inspection | D4: FALSE | E4: 1 | F4: 7 | H4: 0 | I4: =wec_devices -> 1 | J4: 0 | K4: 4 | L4: TRUE | M4: 1.5 | R4: TRUE | S4: V201 - CTV | T4: =IFERROR(IF(ISBLANK(S4),"",INDEX(Gen_Vessels!$A$3:$C$500,MATCH(InspectionSite!$S4,Gen_Vessels!$C$3:$C$500,0),1)),"") -> V201 | U4: 1 | W4: =IFERROR(IF(ISBLANK(V4),"",INDEX(Gen_Vessels!$A$3:$C$500,MATCH(InspectionSite!$V4,Gen_Vessels!$C$3:$C$500,0),1)),"") | Z4: 2 | AD4: device
A5: =IF(ISBLANK($B5)=FALSE,IF(AND($H5>0,$I5<=0,$J5<=0),_xlfn.CONCAT("ofw_",$B5),IF(AND($H5<=0,$I5>0,$J5<=0),_xlfn.CONCAT("owc_",$B5),IF(AND($H5<=0,$I5<=0,$J5>0),_xlfn.CONCAT("opv_",$B5),_xlfn.CONCAT("oce_",$B5)))),"") -> owc_CPO_U1 | B5: CPO_U1 | C5: UAV Inspection | D5: FALSE | E5: 1 | F5: 7 | H5: 0 | I5: =wec_devices -> 1 | J5: 0 | K5: 0.25 | L5: TRUE | M5: 1.5 | R5: TRUE | S5: V201 - CTV | T5: =IFERROR(IF(ISBLANK(S5),"",INDEX(Gen_Vessels!$A$3:$C$500,MATCH(InspectionSite!$S5,Gen_Vessels!$C$3:$C$500,0),1)),"") -> V201 | U5: 1 | W5: =IFERROR(IF(ISBLANK(V5),"",INDEX(Gen_Vessels!$A$3:$C$500,MATCH(InspectionSite!$V5,Gen_Vessels!$C$3:$C$500,0),1)),"") | Y5: EVA_AUV_1 | Z5: 2 | AD5: device
A6: =IF(ISBLANK($B6)=FALSE,IF(AND($H6>0,$I6<=0,$J6<=0),_xlfn.CONCAT("ofw_",$B6),IF(AND($H6<=0,$I6>0,$J6<=0),_xlfn.CONCAT("owc_",$B6),IF(AND($H6<=0,$I6<=0,$J6>0),_xlfn.CONCAT("opv_",$B6),_xlfn.CONCAT("oce_",$B6)))),"") -> owc_CPO_M1 | B6: CPO_M1 | C6: Mooring inspection | D6: FALSE | E6: 1 | F6: 7 | H6: 0 | I6: =wec_devices -> 1 | J6: 0 | K6: 4 | L6: TRUE | M6: 1.5 | R6: TRUE | S6: V201 - CTV | T6: =IFERROR(IF(ISBLANK(S6),"",INDEX(Gen_Vessels!$A$3:$C$500,MATCH(InspectionSite!$S6,Gen_Vessels!$C$3:$C$500,0),1)),"") -> V201 | U6: 1 | W6: =IFERROR(IF(ISBLANK(V6),"",INDEX(Gen_Vessels!$A$3:$C$500,MATCH(InspectionSite!$V6,Gen_Vessels!$C$3:$C$500,0),1)),"") | Z6: 2 | AD6: device
A7: =IF(ISBLANK($B7)=FALSE,IF(AND($H7>0,$I7<=0,$J7<=0),_xlfn.CONCAT("ofw_",$B7),IF(AND($H7<=0,$I7>0,$J7<=0),_xlfn.CONCAT("owc_",$B7),IF(AND($H7<=0,$I7<=0,$J7>0),_xlfn.CONCAT("opv_",$B7),_xlfn.CONCAT("oce_",$B7)))),"") -> owc_CPO_A5 | B7: CPO_A5 | C7: PTO inspection | D7: FALSE | E7: 1 | F7: 7 | H7: 0 | I7: =wec_devices -> 1 | J7: 0 | K7: 3 | L7: TRUE | M7: 1.5 | R7: TRUE | S7: V201 - CTV | T7: =IFERROR(IF(ISBLANK(S7),"",INDEX(Gen_Vessels!$A$3:$C$500,MATCH(InspectionSite!$S7,Gen_Vessels!$C$3:$C$500,0),1)),"") -> V201 | U7: 1 | W7: =IFERROR(IF(ISBLANK(V7),"",INDEX(Gen_Vessels!$A$3:$C$500,MATCH(InspectionSite!$V7,Gen_Vessels!$C$3:$C$500,0),1)),"") | Z7: 2 | AD7: device
A8: =IF(ISBLANK($B8)=FALSE,IF(AND($H8>0,$I8<=0,$J8<=0),_xlfn.CONCAT("ofw_",$B8),IF(AND($H8<=0,$I8>0,$J8<=0),_xlfn.CONCAT("owc_",$B8),IF(AND($H8<=0,$I8<=0,$J8>0),_xlfn.CONCAT("opv_",$B8),_xlfn.CONCAT("oce_",$B8)))),"") | T8: =IFERROR(IF(ISBLANK(S8),"",INDEX(Gen_Vessels!$A$3:$C$500,MATCH(InspectionSite!$S8,Gen_Vessels!$C$3:$C$500,0),1)),"") | W8: =IFERROR(IF(ISBLANK(V8),"",INDEX(Gen_Vessels!$A$3:$C$500,MATCH(InspectionSite!$V8,Gen_Vessels!$C$3:$C$500,0),1)),"")
A9: =IF(ISBLANK($B9)=FALSE,IF(AND($H9>0,$I9<=0,$J9<=0),_xlfn.CONCAT("ofw_",$B9),IF(AND($H9<=0,$I9>0,$J9<=0),_xlfn.CONCAT("owc_",$B9),IF(AND($H9<=0,$I9<=0,$J9>0),_xlfn.CONCAT("opv_",$B9),_xlfn.CONCAT("oce_",$B9)))),"") | T9: =IFERROR(IF(ISBLANK(S9),"",INDEX(Gen_Vessels!$A$3:$C$500,MATCH(InspectionSite!$S9,Gen_Vessels!$C$3:$C$500,0),1)),"") | W9: =IFERROR(IF(ISBLANK(V9),"",INDEX(Gen_Vessels!$A$3:$C$500,MATCH(InspectionSite!$V9,Gen_Vessels!$C$3:$C$500,0),1)),"")
A10: =IF(ISBLANK($B10)=FALSE,IF(AND($H10>0,$I10<=0,$J10<=0),_xlfn.CONCAT("ofw_",$B10),IF(AND($H10<=0,$I10>0,$J10<=0),_xlfn.CONCAT("owc_",$B10),IF(AND($H10<=0,$I10<=0,$J10>0),_xlfn.CONCAT("opv_",$B10),_xlfn.CONCAT("oce_",$B10)))),"") | T10: =IFERROR(IF(ISBLANK(S10),"",INDEX(Gen_Vessels!$A$3:$C$500,MATCH(InspectionSite!$S10,Gen_Vessels!$C$3:$C$500,0),1)),"") | W10: =IFERROR(IF(ISBLANK(V10),"",INDEX(Gen_Vessels!$A$3:$C$500,MATCH(InspectionSite!$V10,Gen_Vessels!$C$3:$C$500,0),1)),"")
A11: =IF(ISBLANK($B11)=FALSE,IF(AND($H11>0,$I11<=0,$J11<=0),_xlfn.CONCAT("ofw_",$B11),IF(AND($H11<=0,$I11>0,$J11<=0),_xlfn.CONCAT("owc_",$B11),IF(AND($H11<=0,$I11<=0,$J11>0),_xlfn.CONCAT("opv_",$B11),_xlfn.CONCAT("oce_",$B11)))),"") | T11: =IFERROR(IF(ISBLANK(S11),"",INDEX(Gen_Vessels!$A$3:$C$500,MATCH(InspectionSite!$S11,Gen_Vessels!$C$3:$C$500,0),1)),"") | W11: =IFERROR(IF(ISBLANK(V11),"",INDEX(Gen_Vessels!$A$3:$C$500,MATCH(InspectionSite!$V11,Gen_Vessels!$C$3:$C$500,0),1)),"")
A12: =IF(ISBLANK($B12)=FALSE,IF(AND($H12>0,$I12<=0,$J12<=0),_xlfn.CONCAT("ofw_",$B12),IF(AND($H12<=0,$I12>0,$J12<=0),_xlfn.CONCAT("owc_",$B12),IF(AND($H12<=0,$I12<=0,$J12>0),_xlfn.CONCAT("opv_",$B12),_xlfn.CONCAT("oce_",$B12)))),"") | T12: =IFERROR(IF(ISBLANK(S12),"",INDEX(Gen_Vessels!$A$3:$C$500,MATCH(InspectionSite!$S12,Gen_Vessels!$C$3:$C$500,0),1)),"") | W12: =IFERROR(IF(ISBLANK(V12),"",INDEX(Gen_Vessels!$A$3:$C$500,MATCH(InspectionSite!$V12,Gen_Vessels!$C$3:$C$500,0),1)),"")
A13: =IF(ISBLANK($B13)=FALSE,IF(AND($H13>0,$I13<=0,$J13<=0),_xlfn.CONCAT("ofw_",$B13),IF(AND($H13<=0,$I13>0,$J13<=0),_xlfn.CONCAT("owc_",$B13),IF(AND($H13<=0,$I13<=0,$J13>0),_xlfn.CONCAT("opv_",$B13),_xlfn.CONCAT("oce_",$B13)))),"") | T13: =IFERROR(IF(ISBLANK(S13),"",INDEX(Gen_Vessels!$A$3:$C$500,MATCH(InspectionSite!$S13,Gen_Vessels!$C$3:$C$500,0),1)),"") | W13: =IFERROR(IF(ISBLANK(V13),"",INDEX(Gen_Vessels!$A$3:$C$500,MATCH(InspectionSite!$V13,Gen_Vessels!$C$3:$C$500,0),1)),"")
A14: =IF(ISBLANK($B14)=FALSE,IF(AND($H14>0,$I14<=0,$J14<=0),_xlfn.CONCAT("ofw_",$B14),IF(AND($H14<=0,$I14>0,$J14<=0),_xlfn.CONCAT("owc_",$B14),IF(AND($H14<=0,$I14<=0,$J14>0),_xlfn.CONCAT("opv_",$B14),_xlfn.CONCAT("oce_",$B14)))),"") | T14: =IFERROR(IF(ISBLANK(S14),"",INDEX(Gen_Vessels!$A$3:$C$500,MATCH(InspectionSite!$S14,Gen_Vessels!$C$3:$C$500,0),1)),"") | W14: =IFERROR(IF(ISBLANK(V14),"",INDEX(Gen_Vessels!$A$3:$C$500,MATCH(InspectionSite!$V14,Gen_Vessels!$C$3:$C$500,0),1)),"")
A15: =IF(ISBLANK($B15)=FALSE,IF(AND($H15>0,$I15<=0,$J15<=0),_xlfn.CONCAT("ofw_",$B15),IF(AND($H15<=0,$I15>0,$J15<=0),_xlfn.CONCAT("owc_",$B15),IF(AND($H15<=0,$I15<=0,$J15>0),_xlfn.CONCAT("opv_",$B15),_xlfn.CONCAT("oce_",$B15)))),"") | T15: =IFERROR(IF(ISBLANK(S15),"",INDEX(Gen_Vessels!$A$3:$C$500,MATCH(InspectionSite!$S15,Gen_Vessels!$C$3:$C$500,0),1)),"") | W15: =IFERROR(IF(ISBLANK(V15),"",INDEX(Gen_Vessels!$A$3:$C$500,MATCH(InspectionSite!$V15,Gen_Vessels!$C$3:$C$500,0),1)),"")
A16: =IF(ISBLANK($B16)=FALSE,IF(AND($H16>0,$I16<=0,$J16<=0),_xlfn.CONCAT("ofw_",$B16),IF(AND($H16<=0,$I16>0,$J16<=0),_xlfn.CONCAT("owc_",$B16),IF(AND($H16<=0,$I16<=0,$J16>0),_xlfn.CONCAT("opv_",$B16),_xlfn.CONCAT("oce_",$B16)))),"") | T16: =IFERROR(IF(ISBLANK(S16),"",INDEX(Gen_Vessels!$A$3:$C$500,MATCH(InspectionSite!$S16,Gen_Vessels!$C$3:$C$500,0),1)),"") | W16: =IFERROR(IF(ISBLANK(V16),"",INDEX(Gen_Vessels!$A$3:$C$500,MATCH(InspectionSite!$V16,Gen_Vessels!$C$3:$C$500,0),1)),"")
A17: =IF(ISBLANK($B17)=FALSE,IF(AND($H17>0,$I17<=0,$J17<=0),_xlfn.CONCAT("ofw_",$B17),IF(AND($H17<=0,$I17>0,$J17<=0),_xlfn.CONCAT("owc_",$B17),IF(AND($H17<=0,$I17<=0,$J17>0),_xlfn.CONCAT("opv_",$B17),_xlfn.CONCAT("oce_",$B17)))),"") | T17: =IFERROR(IF(ISBLANK(S17),"",INDEX(Gen_Vessels!$A$3:$C$500,MATCH(InspectionSite!$S17,Gen_Vessels!$C$3:$C$500,0),1)),"") | W17: =IFERROR(IF(ISBLANK(V17),"",INDEX(Gen_Vessels!$A$3:$C$500,MATCH(InspectionSite!$V17,Gen_Vessels!$C$3:$C$500,0),1)),"")
A18: =IF(ISBLANK($B18)=FALSE,IF(AND($H18>0,$I18<=0,$J18<=0),_xlfn.CONCAT("ofw_",$B18),IF(AND($H18<=0,$I18>0,$J18<=0),_xlfn.CONCAT("owc_",$B18),IF(AND($H18<=0,$I18<=0,$J18>0),_xlfn.CONCAT("opv_",$B18),_xlfn.CONCAT("oce_",$B18)))),"") | T18: =IFERROR(IF(ISBLANK(S18),"",INDEX(Gen_Vessels!$A$3:$C$500,MATCH(InspectionSite!$S18,Gen_Vessels!$C$3:$C$500,0),1)),"") | W18: =IFERROR(IF(ISBLANK(V18),"",INDEX(Gen_Vessels!$A$3:$C$500,MATCH(InspectionSite!$V18,Gen_Vessels!$C$3:$C$500,0),1)),"")
A19: =IF(ISBLANK($B19)=FALSE,IF(AND($H19>0,$I19<=0,$J19<=0),_xlfn.CONCAT("ofw_",$B19),IF(AND($H19<=0,$I19>0,$J19<=0),_xlfn.CONCAT("owc_",$B19),IF(AND($H19<=0,$I19<=0,$J19>0),_xlfn.CONCAT("opv_",$B19),_xlfn.CONCAT("oce_",$B19)))),"") | T19: =IFERROR(IF(ISBLANK(S19),"",INDEX(Gen_Vessels!$A$3:$C$500,MATCH(InspectionSite!$S19,Gen_Vessels!$C$3:$C$500,0),1)),"") | W19: =IFERROR(IF(ISBLANK(V19),"",INDEX(Gen_Vessels!$A$3:$C$500,MATCH(InspectionSite!$V19,Gen_Vessels!$C$3:$C$500,0),1)),"")
... A490: =IF(ISBLANK($B490)=FALSE,IF(AND($H490>0,$I490<=0,$J490<=0),_xlfn.CONCAT("ofw_",$B490),IF(AND($H490<=0,$I490>0,$J490<=0),_xlfn.CONCAT("owc_",$B490),IF(AND($H490<=0,$I490<=0,$J490>0),_xlfn.CONCAT("opv_",$B490),_xlfn.CONCAT("oce_",$B490)))),"") | T490: =IFERROR(IF(ISBLANK(S490),"",INDEX(Gen_Vessels!$A$3:$C$500,MATCH(InspectionSite!$S490,Gen_Vessels!$C$3:$C$500,0),1)),"") | W490: =IFERROR(IF(ISBLANK(V490),"",INDEX(Gen_Vessels!$A$3:$C$500,MATCH(InspectionSite!$V490,Gen_Vessels!$C$3:$C$500,0),1)),"")
T491: =IFERROR(IF(ISBLANK(S491),"",INDEX(Gen_Vessels!$A$3:$C$500,MATCH(InspectionSite!$S491,Gen_Vessels!$C$3:$C$500,0),1)),"") | W491: =IFERROR(IF(ISBLANK(V491),"",INDEX(Gen_Vessels!$A$3:$C$500,MATCH(InspectionSite!$V491,Gen_Vessels!$C$3:$C$500,0),1)),"")
T492: =IFERROR(IF(ISBLANK(S492),"",INDEX(Gen_Vessels!$A$3:$C$500,MATCH(InspectionSite!$S492,Gen_Vessels!$C$3:$C$500,0),1)),"") | W492: =IFERROR(IF(ISBLANK(V492),"",INDEX(Gen_Vessels!$A$3:$C$500,MATCH(InspectionSite!$V492,Gen_Vessels!$C$3:$C$500,0),1)),"")
T493: =IFERROR(IF(ISBLANK(S493),"",INDEX(Gen_Vessels!$A$3:$C$500,MATCH(InspectionSite!$S493,Gen_Vessels!$C$3:$C$500,0),1)),"") | W493: =IFERROR(IF(ISBLANK(V493),"",INDEX(Gen_Vessels!$A$3:$C$500,MATCH(InspectionSite!$V493,Gen_Vessels!$C$3:$C$500,0),1)),"")
T494: =IFERROR(IF(ISBLANK(S494),"",INDEX(Gen_Vessels!$A$3:$C$500,MATCH(InspectionSite!$S494,Gen_Vessels!$C$3:$C$500,0),1)),"") | W494: =IFERROR(IF(ISBLANK(V494),"",INDEX(Gen_Vessels!$A$3:$C$500,MATCH(InspectionSite!$V494,Gen_Vessels!$C$3:$C$500,0),1)),"")
T495: =IFERROR(IF(ISBLANK(S495),"",INDEX(Gen_Vessels!$A$3:$C$500,MATCH(InspectionSite!$S495,Gen_Vessels!$C$3:$C$500,0),1)),"") | W495: =IFERROR(IF(ISBLANK(V495),"",INDEX(Gen_Vessels!$A$3:$C$500,MATCH(InspectionSite!$V495,Gen_Vessels!$C$3:$C$500,0),1)),"")
T496: =IFERROR(IF(ISBLANK(S496),"",INDEX(Gen_Vessels!$A$3:$C$500,MATCH(InspectionSite!$S496,Gen_Vessels!$C$3:$C$500,0),1)),"") | W496: =IFERROR(IF(ISBLANK(V496),"",INDEX(Gen_Vessels!$A$3:$C$500,MATCH(InspectionSite!$V496,Gen_Vessels!$C$3:$C$500,0),1)),"")
T497: =IFERROR(IF(ISBLANK(S497),"",INDEX(Gen_Vessels!$A$3:$C$500,MATCH(InspectionSite!$S497,Gen_Vessels!$C$3:$C$500,0),1)),"") | W497: =IFERROR(IF(ISBLANK(V497),"",INDEX(Gen_Vessels!$A$3:$C$500,MATCH(InspectionSite!$V497,Gen_Vessels!$C$3:$C$500,0),1)),"")
T498: =IFERROR(IF(ISBLANK(S498),"",INDEX(Gen_Vessels!$A$3:$C$500,MATCH(InspectionSite!$S498,Gen_Vessels!$C$3:$C$500,0),1)),"") | W498: =IFERROR(IF(ISBLANK(V498),"",INDEX(Gen_Vessels!$A$3:$C$500,MATCH(InspectionSite!$V498,Gen_Vessels!$C$3:$C$500,0),1)),"")

Sheet Operations_prev
A1: id | B1: id_short | C1: name | D1: op_prev | E1: op_next | F1: periodicity | G1: preferred_months | H1: wtg_intervened | I1: wec_intervened | J1: pv_intervened | K1: hs | L1: tp | M1: ws | N1: cs | O1: vessel1 | P1: vessel2 | Q1: rov_drone | R1: technicians_per_device | S1: technician_cost | T1: parts_cost | U1: other_costs
A2: - | B2: - | C2: - | D2: - | E2: - | F2: every X years | G2: - | H2: - | I2: - | J2: - | K2: m | L2: s | M2: m/s | N2: m/s | O2: - | P2: - | Q2: - | R2: - | S2: €/technician/day | T2: € | U2: €
A3: =IF(ISBLANK($B3)=FALSE,IF(AND($H3>0,$I3<=0,$J3<=0),_xlfn.CONCAT("ofw_",$B3),IF(AND($H3<=0,$I3>0,$J3<=0),_xlfn.CONCAT("owc_",$B3),IF(AND($H3<=0,$I3<=0,$J3>0),_xlfn.CONCAT("opv_",$B3),_xlfn.CONCAT("oce_",$B3)))),"") -> owc_CPO_A1 | B3: CPO_A1 | C3: WEC visual inspection | F3: 0.5 | G3: 04, 05, 10, 11 | H3: 0 | I3: =wec_devices -> 1 | J3: 0 | O3: V101 - CTV | R3: 2 | S3: 300 | T3: =1830*I3 -> 1830
A4: =IF(ISBLANK($B4)=FALSE,IF(AND($H4>0,$I4<=0,$J4<=0),_xlfn.CONCAT("ofw_",$B4),IF(AND($H4<=0,$I4>0,$J4<=0),_xlfn.CONCAT("owc_",$B4),IF(AND($H4<=0,$I4<=0,$J4>0),_xlfn.CONCAT("opv_",$B4),_xlfn.CONCAT("oce_",$B4)))),"") -> owc_CPO_A2 | B4: CPO_A2 | C4: WEC visual inspection and filter replacement | F4: 1 | G4: 06, 07, 08, 09 | H4: 0 | I4: =wec_devices -> 1 | J4: 0 | O4: V101 - CTV | R4: 2 | S4: 300 | T4: =5175*I4 -> 5175
A5: =IF(ISBLANK($B5)=FALSE,IF(AND($H5>0,$I5<=0,$J5<=0),_xlfn.CONCAT("ofw_",$B5),IF(AND($H5<=0,$I5>0,$J5<=0),_xlfn.CONCAT("owc_",$B5),IF(AND($H5<=0,$I5<=0,$J5>0),_xlfn.CONCAT("opv_",$B5),_xlfn.CONCAT("oce_",$B5)))),"") -> owc_CPO_A3_0 | B5: CPO_A3_0 | C5: WEC removal | H5: 0 | I5: =wec_devices -> 1 | J5: 0 | O5: V006 - Multicat | R5: 1 | S5: 200
A6: =IF(ISBLANK($B6)=FALSE,IF(AND($H6>0,$I6<=0,$J6<=0),_xlfn.CONCAT("ofw_",$B6),IF(AND($H6<=0,$I6>0,$J6<=0),_xlfn.CONCAT("owc_",$B6),IF(AND($H6<=0,$I6<=0,$J6>0),_xlfn.CONCAT("opv_",$B6),_xlfn.CONCAT("oce_",$B6)))),"") -> owc_CPO_A3_1 | B6: CPO_A3_1 | C6: WEC on land inspection | D6: owc_CPO_A3_0 | E6: owc_CPO_A3_3 | F6: 5 | G6: 06, 07, 08, 09 | H6: 0 | I6: =wec_devices/2 -> 0.5 | J6: 0 | R6: 3 | S6: 300 | T6: =9962.5*I6 -> 4981.25
A7: =IF(ISBLANK($B7)=FALSE,IF(AND($H7>0,$I7<=0,$J7<=0),_xlfn.CONCAT("ofw_",$B7),IF(AND($H7<=0,$I7>0,$J7<=0),_xlfn.CONCAT("owc_",$B7),IF(AND($H7<=0,$I7<=0,$J7>0),_xlfn.CONCAT("opv_",$B7),_xlfn.CONCAT("oce_",$B7)))),"") -> owc_CPO_A3_2 | B7: CPO_A3_2 | C7: WEC on land replacement | D7: owc_CPO_A3_0 | E7: owc_CPO_A3_3 | F7: 5 | G7: 06, 07, 08, 09 | H7: 0 | I7: =wec_devices/2 -> 0.5 | J7: 0 | R7: 3 | S7: 300 | T7: =9962.5*I7 -> 4981.25
A8: =IF(ISBLANK($B8)=FALSE,IF(AND($H8>0,$I8<=0,$J8<=0),_xlfn.CONCAT("ofw_",$B8),IF(AND($H8<=0,$I8>0,$J8<=0),_xlfn.CONCAT("owc_",$B8),IF(AND($H8<=0,$I8<=0,$J8>0),_xlfn.CONCAT("opv_",$B8),_xlfn.CONCAT("oce_",$B8)))),"") -> owc_CPO_A3_3 | B8: CPO_A3_3 | C8: WEC re-deploy | H8: 0 | I8: =wec_devices -> 1 | J8: 0 | O8: V006 - Multicat | R8: 1 | S8: 200
A9: =IF(ISBLANK($B9)=FALSE,IF(AND($H9>0,$I9<=0,$J9<=0),_xlfn.CONCAT("ofw_",$B9),IF(AND($H9<=0,$I9>0,$J9<=0),_xlfn.CONCAT("owc_",$B9),IF(AND($H9<=0,$I9<=0,$J9>0),_xlfn.CONCAT("opv_",$B9),_xlfn.CONCAT("oce_",$B9)))),"") -> oce_SuAB_1 | B9: SuAB_1 | C9: Visual inspection - blades | F9: 1 | G9: 04, 05, 06, 07, 08, 09 | H9: =wtg_devices -> 0 | I9: 0 | J9: 0 | O9: V005 - CTV | Q9: stork_1 - Stork (Aerial) | R9: 3 | S9: 300
A10: =IF(ISBLANK($B10)=FALSE,IF(AND($H10>0,$I10<=0,$J10<=0),_xlfn.CONCAT("ofw_",$B10),IF(AND($H10<=0,$I10>0,$J10<=0),_xlfn.CONCAT("owc_",$B10),IF(AND($H10<=0,$I10<=0,$J10>0),_xlfn.CONCAT("opv_",$B10),_xlfn.CONCAT("oce_",$B10)))),"") -> oce_SuAB_2 | B10: SuAB_2 | C10: Drive train inspection | F10: 1 | G10: 04, 05, 06, 07, 08, 09 | H10: =wtg_devices -> 0 | I10: 0 | J10: 0 | O10: V101 - CTV | R10: 3 | S10: 200
A11: =IF(ISBLANK($B11)=FALSE,IF(AND($H11>0,$I11<=0,$J11<=0),_xlfn.CONCAT("ofw_",$B11),IF(AND($H11<=0,$I11>0,$J11<=0),_xlfn.CONCAT("owc_",$B11),IF(AND($H11<=0,$I11<=0,$J11>0),_xlfn.CONCAT("opv_",$B11),_xlfn.CONCAT("oce_",$B11)))),"") -> oce_SuAB_3 | B11: SuAB_3 | C11: Inspection of control system and electrical | F11: 1 | G11: 04, 05, 06, 07, 08, 09 | H11: =wtg_devices -> 0 | I11: 0 | J11: 0 | O11: V005 - CTV | R11: 3 | S11: 200
A12: =IF(ISBLANK($B12)=FALSE,IF(AND($H12>0,$I12<=0,$J12<=0),_xlfn.CONCAT("ofw_",$B12),IF(AND($H12<=0,$I12>0,$J12<=0),_xlfn.CONCAT("owc_",$B12),IF(AND($H12<=0,$I12<=0,$J12>0),_xlfn.CONCAT("opv_",$B12),_xlfn.CONCAT("oce_",$B12)))),"") -> oce_SuAB_4 | B12: SuAB_4 | C12: Inspection of hydraulic and pneumatic systems | F12: 1 | G12: 04, 05, 06, 07, 08, 09 | H12: =wtg_devices -> 0 | I12: 0 | J12: 0 | O12: V005 - CTV | R12: 3 | S12: 200
A13: =IF(ISBLANK($B13)=FALSE,IF(AND($H13>0,$I13<=0,$J13<=0),_xlfn.CONCAT("ofw_",$B13),IF(AND($H13<=0,$I13>0,$J13<=0),_xlfn.CONCAT("owc_",$B13),IF(AND($H13<=0,$I13<=0,$J13>0),_xlfn.CONCAT("opv_",$B13),_xlfn.CONCAT("oce_",$B13)))),"") -> oce_SuAB_5 | B13: SuAB_5 | C13: Visual inspection to tower | F13: 1 | G13: 04, 05, 06, 07, 08, 09 | H13: =wtg_devices -> 0 | I13: 0 | J13: 0 | O13: V005 - CTV | R13: 2 | S13: 300
A14: =IF(ISBLANK($B14)=FALSE,IF(AND($H14>0,$I14<=0,$J14<=0),_xlfn.CONCAT("ofw_",$B14),IF(AND($H14<=0,$I14>0,$J14<=0),_xlfn.CONCAT("owc_",$B14),IF(AND($H14<=0,$I14<=0,$J14>0),_xlfn.CONCAT("opv_",$B14),_xlfn.CONCAT("oce_",$B14)))),"") -> oce_SuAB_6 | B14: SuAB_6 | C14: Inspection of mooring system (3 mooring lines) | F14: 1 | G14: 04, 05, 06, 07, 08, 09 | H14: =wtg_devices -> 0 | I14: 0 | J14: 0 | O14: V004 - DSV | R14: 6 | S14: 600
A15: =IF(ISBLANK($B15)=FALSE,IF(AND($H15>0,$I15<=0,$J15<=0),_xlfn.CONCAT("ofw_",$B15),IF(AND($H15<=0,$I15>0,$J15<=0),_xlfn.CONCAT("owc_",$B15),IF(AND($H15<=0,$I15<=0,$J15>0),_xlfn.CONCAT("opv_",$B15),_xlfn.CONCAT("oce_",$B15)))),"") -> oce_SuAB_cable_1 | B15: SuAB_cable_1 | C15: Inspection of WTG dynamic power cables | F15: 2 | G15: 04, 05, 06, 07, 08, 09 | H15: =wtg_devices -> 0 | I15: 0 | J15: 0 | O15: V004 - DSV | R15: 6 | S15: 600
A16: =IF(ISBLANK($B16)=FALSE,IF(AND($H16>0,$I16<=0,$J16<=0),_xlfn.CONCAT("ofw_",$B16),IF(AND($H16<=0,$I16>0,$J16<=0),_xlfn.CONCAT("owc_",$B16),IF(AND($H16<=0,$I16<=0,$J16>0),_xlfn.CONCAT("opv_",$B16),_xlfn.CONCAT("oce_",$B16)))),"") -> oce_SuAB_cable_2 | B16: SuAB_cable_2 | C16: Inspection of export power cables | F16: 2 | G16: 04, 05, 06, 07, 08, 09 | H16: 0 | I16: 0 | J16: 0 | O16: V004 - DSV | R16: 6 | S16: 600
A17: =IF(ISBLANK($B17)=FALSE,IF(AND($H17>0,$I17<=0,$J17<=0),_xlfn.CONCAT("ofw_",$B17),IF(AND($H17<=0,$I17>0,$J17<=0),_xlfn.CONCAT("owc_",$B17),IF(AND($H17<=0,$I17<=0,$J17>0),_xlfn.CONCAT("opv_",$B17),_xlfn.CONCAT("oce_",$B17)))),"") -> owc_OP001 | B17: OP001 | C17: General inspection | F17: 1 | G17: 06, 07, 08, 09 | H17: =ROUND(wtg_devices*2/3,0) -> 0 | I17: =ROUND(wec_devices*2/3,0) -> 1 | J17: 0 | O17: V101 - CTV | R17: 3 | S17: 200 | U17: 10000
A18: =IF(ISBLANK($B18)=FALSE,IF(AND($H18>0,$I18<=0,$J18<=0),_xlfn.CONCAT("ofw_",$B18),IF(AND($H18<=0,$I18>0,$J18<=0),_xlfn.CONCAT("owc_",$B18),IF(AND($H18<=0,$I18<=0,$J18>0),_xlfn.CONCAT("opv_",$B18),_xlfn.CONCAT("oce_",$B18)))),"") -> owc_OP002 | B18: OP002 | C18: Underwater inspection | F18: 2 | H18: =ROUND(wtg_devices*2/3,0) -> 0 | I18: =ROUND(wec_devices*2/3,0) -> 1 | J18: 0 | O18: V004 - DSV | R18: 6 | S18: 600 | U18: 10000
A19: =IF(ISBLANK($B19)=FALSE,IF(AND($H19>0,$I19<=0,$J19<=0),_xlfn.CONCAT("ofw_",$B19),IF(AND($H19<=0,$I19>0,$J19<=0),_xlfn.CONCAT("owc_",$B19),IF(AND($H19<=0,$I19<=0,$J19>0),_xlfn.CONCAT("opv_",$B19),_xlfn.CONCAT("oce_",$B19)))),"") -> oce_OP003 | B19: OP003 | C19: General inspection with drone | F19: 1 | G19: 06, 07, 08, 09 | H19: =wtg_devices -> 0 | J19: =pv_islands -> 0 | O19: V101 - CTV | Q19: stork_1 - Stork (Aerial) | R19: 3 | S19: 400 | U19: 3000
A20: =IF(ISBLANK($B20)=FALSE,IF(AND($H20>0,$I20<=0,$J20<=0),_xlfn.CONCAT("ofw_",$B20),IF(AND($H20<=0,$I20>0,$J20<=0),_xlfn.CONCAT("owc_",$B20),IF(AND($H20<=0,$I20<=0,$J20>0),_xlfn.CONCAT("opv_",$B20),_xlfn.CONCAT("oce_",$B20)))),"")
A21: =IF(ISBLANK($B21)=FALSE,IF(AND($H21>0,$I21<=0,$J21<=0),_xlfn.CONCAT("ofw_",$B21),IF(AND($H21<=0,$I21>0,$J21<=0),_xlfn.CONCAT("owc_",$B21),IF(AND($H21<=0,$I21<=0,$J21>0),_xlfn.CONCAT("opv_",$B21),_xlfn.CONCAT("oce_",$B21)))),"")
A22: =IF(ISBLANK($B22)=FALSE,IF(AND($H22>0,$I22<=0,$J22<=0),_xlfn.CONCAT("ofw_",$B22),IF(AND($H22<=0,$I22>0,$J22<=0),_xlfn.CONCAT("owc_",$B22),IF(AND($H22<=0,$I22<=0,$J22>0),_xlfn.CONCAT("opv_",$B22),_xlfn.CONCAT("oce_",$B22)))),"")
A23: =IF(ISBLANK($B23)=FALSE,IF(AND($H23>0,$I23<=0,$J23<=0),_xlfn.CONCAT("ofw_",$B23),IF(AND($H23<=0,$I23>0,$J23<=0),_xlfn.CONCAT("owc_",$B23),IF(AND($H23<=0,$I23<=0,$J23>0),_xlfn.CONCAT("opv_",$B23),_xlfn.CONCAT("oce_",$B23)))),"")
A24: =IF(ISBLANK($B24)=FALSE,IF(AND($H24>0,$I24<=0,$J24<=0),_xlfn.CONCAT("ofw_",$B24),IF(AND($H24<=0,$I24>0,$J24<=0),_xlfn.CONCAT("owc_",$B24),IF(AND($H24<=0,$I24<=0,$J24>0),_xlfn.CONCAT("opv_",$B24),_xlfn.CONCAT("oce_",$B24)))),"")
A25: =IF(ISBLANK($B25)=FALSE,IF(AND($H25>0,$I25<=0,$J25<=0),_xlfn.CONCAT("ofw_",$B25),IF(AND($H25<=0,$I25>0,$J25<=0),_xlfn.CONCAT("owc_",$B25),IF(AND($H25<=0,$I25<=0,$J25>0),_xlfn.CONCAT("opv_",$B25),_xlfn.CONCAT("oce_",$B25)))),"")
A26: =IF(ISBLANK($B26)=FALSE,IF(AND($H26>0,$I26<=0,$J26<=0),_xlfn.CONCAT("ofw_",$B26),IF(AND($H26<=0,$I26>0,$J26<=0),_xlfn.CONCAT("owc_",$B26),IF(AND($H26<=0,$I26<=0,$J26>0),_xlfn.CONCAT("opv_",$B26),_xlfn.CONCAT("oce_",$B26)))),"")
A27: =IF(ISBLANK($B27)=FALSE,IF(AND($H27>0,$I27<=0,$J27<=0),_xlfn.CONCAT("ofw_",$B27),IF(AND($H27<=0,$I27>0,$J27<=0),_xlfn.CONCAT("owc_",$B27),IF(AND($H27<=0,$I27<=0,$J27>0),_xlfn.CONCAT("opv_",$B27),_xlfn.CONCAT("oce_",$B27)))),"")
A28: =IF(ISBLANK($B28)=FALSE,IF(AND($H28>0,$I28<=0,$J28<=0),_xlfn.CONCAT("ofw_",$B28),IF(AND($H28<=0,$I28>0,$J28<=0),_xlfn.CONCAT("owc_",$B28),IF(AND($H28<=0,$I28<=0,$J28>0),_xlfn.CONCAT("opv_",$B28),_xlfn.CONCAT("oce_",$B28)))),"")
A29: =IF(ISBLANK($B29)=FALSE,IF(AND($H29>0,$I29<=0,$J29<=0),_xlfn.CONCAT("ofw_",$B29),IF(AND($H29<=0,$I29>0,$J29<=0),_xlfn.CONCAT("owc_",$B29),IF(AND($H29<=0,$I29<=0,$J29>0),_xlfn.CONCAT("opv_",$B29),_xlfn.CONCAT("oce_",$B29)))),"")
A30: =IF(ISBLANK($B30)=FALSE,IF(AND($H30>0,$I30<=0,$J30<=0),_xlfn.CONCAT("ofw_",$B30),IF(AND($H30<=0,$I30>0,$J30<=0),_xlfn.CONCAT("owc_",$B30),IF(AND($H30<=0,$I30<=0,$J30>0),_xlfn.CONCAT("opv_",$B30),_xlfn.CONCAT("oce_",$B30)))),"")
A31: =IF(ISBLANK($B31)=FALSE,IF(AND($H31>0,$I31<=0,$J31<=0),_xlfn.CONCAT("ofw_",$B31),IF(AND($H31<=0,$I31>0,$J31<=0),_xlfn.CONCAT("owc_",$B31),IF(AND($H31<=0,$I31<=0,$J31>0),_xlfn.CONCAT("opv_",$B31),_xlfn.CONCAT("oce_",$B31)))),"")
... A494: =IF(ISBLANK($B494)=FALSE,IF(AND($H494>0,$I494<=0,$J494<=0),_xlfn.CONCAT("ofw_",$B494),IF(AND($H494<=0,$I494>0,$J494<=0),_xlfn.CONCAT("owc_",$B494),IF(AND($H494<=0,$I494<=0,$J494>0),_xlfn.CONCAT("opv_",$B494),_xlfn.CONCAT("oce_",$B494)))),"")

Sheet InspectionPort
A1: id | B1: id_short | C1: name | D1: periodicity | E1: preferred_months | F1: day_start | G1: devices_intervened | H1: dur_per_device | I1: level | J1: ws | K1: light | L1: technicians_per_device | M1: technician_cost | N1: parts_cost | O1: other_costs | P1: port_costs | Q1: double_shift
A2: - | B2: - | C2: - | D2: every X years | E2: - | F2: - | G2: - | H2: h | I2: - | J2: m/s | K2: - | L2: - | M2: €/technician/day | N2: € | O2: € | P2: €/day | Q2: -
A3: =IF(ISBLANK($B3)=FALSE,_xlfn.CONCAT("owc_",$B3),"") -> owc_CPO_P1 | B3: CPO_P1 | C3: WEC maintenance | D3: 1 | G3: 1 | H3: 168 | I3: hub | L3: 3 | M3: 0 | Q3: TRUE
A4: =IF(ISBLANK($B4)=FALSE,_xlfn.CONCAT("owc_",$B4),"")
A5: =IF(ISBLANK($B5)=FALSE,_xlfn.CONCAT("owc_",$B5),"")
A6: =IF(ISBLANK($B6)=FALSE,_xlfn.CONCAT("owc_",$B6),"")
A7: =IF(ISBLANK($B7)=FALSE,_xlfn.CONCAT("owc_",$B7),"")
A8: =IF(ISBLANK($B8)=FALSE,_xlfn.CONCAT("owc_",$B8),"")
A9: =IF(ISBLANK($B9)=FALSE,_xlfn.CONCAT("owc_",$B9),"")
A10: =IF(ISBLANK($B10)=FALSE,_xlfn.CONCAT("owc_",$B10),"")
A11: =IF(ISBLANK($B11)=FALSE,_xlfn.CONCAT("owc_",$B11),"")
A12: =IF(ISBLANK($B12)=FALSE,_xlfn.CONCAT("owc_",$B12),"")
A13: =IF(ISBLANK($B13)=FALSE,_xlfn.CONCAT("owc_",$B13),"")
A14: =IF(ISBLANK($B14)=FALSE,_xlfn.CONCAT("owc_",$B14),"")
A15: =IF(ISBLANK($B15)=FALSE,_xlfn.CONCAT("owc_",$B15),"")
... A69: =IF(ISBLANK($B69)=FALSE,_xlfn.CONCAT("owc_",$B69),"")

Sheet CorrectiveMinor
A1: id | B1: id_short | C1: name | D1: wtg | E1: wec | F1: pv | G1: duration_net | H1: device_shutdown | I1: hs | J1: tp | K1: ws | L1: ws_hub | M1: cs | N1: light | O1: vessel1 | P1: vessel1_id | Q1: vessel1_qt | R1: vessel2 | S1: vessel2_id | T1: vessel2_qt | U1: rov_drone | V1: technicians | W1: technician_cost | X1: parts_cost | Y1: other_costs | Z1: level | AA1: double_shift
A2: - | B2: - | C2: - | D2: - | E2: - | F2: - | G2: h | H2: - | I2: m | J2: s | K2: m/s | L2: m/s | M2: m/s | N2: - | O2: - | P2: - | Q2: - | R2: - | S2: - | T2: - | U2: - | V2: - | W2: €/technician/day | X2: € | Y2: € | Z2: - | AA2: -
A3: =IF(ISBLANK($B3)=FALSE,IF(AND($D3>0,$E3<=0,$F3<=0),_xlfn.CONCAT("ofw_",$B3),IF(AND($D3<=0,$E3>0,$F3<=0),_xlfn.CONCAT("owc_",$B3),IF(AND($D3<=0,$E3<=0,$F3>0),_xlfn.CONCAT("opv_",$B3),_xlfn.CONCAT("oce_",$B3)))),"") -> owc_M01 | B3: M01 | C3: M01 - Inverter | E3: x | G3: 2 | H3: TRUE | I3: 1.5 | N3: TRUE | O3: V101 - CTV | P3: =IFERROR(IF(ISBLANK(O3),"",INDEX(Gen_Vessels!$A$3:$C$500,MATCH(O3,Gen_Vessels!$C$3:$C$500,0),1)),"") -> V101 | Q3: 1 | S3: =IFERROR(IF(ISBLANK(R3),"",INDEX(Gen_Vessels!$A$3:$C$500,MATCH(CorrectiveMinor!$R3,Gen_Vessels!$C$3:$C$500,0),1)),"") | T3: 1 | V3: 2 | W3: 0 | Z3: device
A4: =IF(ISBLANK($B4)=FALSE,IF(AND($D4>0,$E4<=0,$F4<=0),_xlfn.CONCAT("ofw_",$B4),IF(AND($D4<=0,$E4>0,$F4<=0),_xlfn.CONCAT("owc_",$B4),IF(AND($D4<=0,$E4<=0,$F4>0),_xlfn.CONCAT("opv_",$B4),_xlfn.CONCAT("oce_",$B4)))),"") -> owc_M02 | B4: M02 | C4: M02 - C-gen | E4: x | G4: 2 | H4: TRUE | I4: 1.5 | N4: TRUE | O4: V101 - CTV | P4: =IFERROR(IF(ISBLANK(O4),"",INDEX(Gen_Vessels!$A$3:$C$500,MATCH(O4,Gen_Vessels!$C$3:$C$500,0),1)),"") -> V101 | Q4: 1 | S4: =IFERROR(IF(ISBLANK(R4),"",INDEX(Gen_Vessels!$A$3:$C$500,MATCH(CorrectiveMinor!$R4,Gen_Vessels!$C$3:$C$500,0),1)),"") | T4: 1 | V4: 2 | W4: 0 | Z4: device
A5: =IF(ISBLANK($B5)=FALSE,IF(AND($D5>0,$E5<=0,$F5<=0),_xlfn.CONCAT("ofw_",$B5),IF(AND($D5<=0,$E5>0,$F5<=0),_xlfn.CONCAT("owc_",$B5),IF(AND($D5<=0,$E5<=0,$F5>0),_xlfn.CONCAT("opv_",$B5),_xlfn.CONCAT("oce_",$B5)))),"") -> owc_M03 | B5: M03 | C5: M03 - PTO | E5: x | G5: 4 | H5: TRUE | I5: 1.5 | N5: TRUE | O5: V101 - CTV | P5: =IFERROR(IF(ISBLANK(O5),"",INDEX(Gen_Vessels!$A$3:$C$500,MATCH(O5,Gen_Vessels!$C$3:$C$500,0),1)),"") -> V101 | Q5: 1 | S5: =IFERROR(IF(ISBLANK(R5),"",INDEX(Gen_Vessels!$A$3:$C$500,MATCH(CorrectiveMinor!$R5,Gen_Vessels!$C$3:$C$500,0),1)),"") | T5: 1 | V5: 2 | W5: 0 | Z5: device
A6: =IF(ISBLANK($B6)=FALSE,IF(AND($D6>0,$E6<=0,$F6<=0),_xlfn.CONCAT("ofw_",$B6),IF(AND($D6<=0,$E6>0,$F6<=0),_xlfn.CONCAT("owc_",$B6),IF(AND($D6<=0,$E6<=0,$F6>0),_xlfn.CONCAT("opv_",$B6),_xlfn.CONCAT("oce_",$B6)))),"") | P6: =IFERROR(IF(ISBLANK(O6),"",INDEX(Gen_Vessels!$A$3:$C$500,MATCH(O6,Gen_Vessels!$C$3:$C$500,0),1)),"") | S6: =IFERROR(IF(ISBLANK(R6),"",INDEX(Gen_Vessels!$A$3:$C$500,MATCH(CorrectiveMinor!$R6,Gen_Vessels!$C$3:$C$500,0),1)),"")
A7: =IF(ISBLANK($B7)=FALSE,IF(AND($D7>0,$E7<=0,$F7<=0),_xlfn.CONCAT("ofw_",$B7),IF(AND($D7<=0,$E7>0,$F7<=0),_xlfn.CONCAT("owc_",$B7),IF(AND($D7<=0,$E7<=0,$F7>0),_xlfn.CONCAT("opv_",$B7),_xlfn.CONCAT("oce_",$B7)))),"") | P7: =IFERROR(IF(ISBLANK(O7),"",INDEX(Gen_Vessels!$A$3:$C$500,MATCH(O7,Gen_Vessels!$C$3:$C$500,0),1)),"") | S7: =IFERROR(IF(ISBLANK(R7),"",INDEX(Gen_Vessels!$A$3:$C$500,MATCH(CorrectiveMinor!$R7,Gen_Vessels!$C$3:$C$500,0),1)),"")
A8: =IF(ISBLANK($B8)=FALSE,IF(AND($D8>0,$E8<=0,$F8<=0),_xlfn.CONCAT("ofw_",$B8),IF(AND($D8<=0,$E8>0,$F8<=0),_xlfn.CONCAT("owc_",$B8),IF(AND($D8<=0,$E8<=0,$F8>0),_xlfn.CONCAT("opv_",$B8),_xlfn.CONCAT("oce_",$B8)))),"") | P8: =IFERROR(IF(ISBLANK(O8),"",INDEX(Gen_Vessels!$A$3:$C$500,MATCH(O8,Gen_Vessels!$C$3:$C$500,0),1)),"") | S8: =IFERROR(IF(ISBLANK(R8),"",INDEX(Gen_Vessels!$A$3:$C$500,MATCH(CorrectiveMinor!$R8,Gen_Vessels!$C$3:$C$500,0),1)),"")
A9: =IF(ISBLANK($B9)=FALSE,IF(AND($D9>0,$E9<=0,$F9<=0),_xlfn.CONCAT("ofw_",$B9),IF(AND($D9<=0,$E9>0,$F9<=0),_xlfn.CONCAT("owc_",$B9),IF(AND($D9<=0,$E9<=0,$F9>0),_xlfn.CONCAT("opv_",$B9),_xlfn.CONCAT("oce_",$B9)))),"") | P9: =IFERROR(IF(ISBLANK(O9),"",INDEX(Gen_Vessels!$A$3:$C$500,MATCH(O9,Gen_Vessels!$C$3:$C$500,0),1)),"") | S9: =IFERROR(IF(ISBLANK(R9),"",INDEX(Gen_Vessels!$A$3:$C$500,MATCH(CorrectiveMinor!$R9,Gen_Vessels!$C$3:$C$500,0),1)),"")
A10: =IF(ISBLANK($B10)=FALSE,IF(AND($D10>0,$E10<=0,$F10<=0),_xlfn.CONCAT("ofw_",$B10),IF(AND($D10<=0,$E10>0,$F10<=0),_xlfn.CONCAT("owc_",$B10),IF(AND($D10<=0,$E10<=0,$F10>0),_xlfn.CONCAT("opv_",$B10),_xlfn.CONCAT("oce_",$B10)))),"") | P10: =IFERROR(IF(ISBLANK(O10),"",INDEX(Gen_Vessels!$A$3:$C$500,MATCH(O10,Gen_Vessels!$C$3:$C$500,0),1)),"") | S10: =IFERROR(IF(ISBLANK(R10),"",INDEX(Gen_Vessels!$A$3:$C$500,MATCH(CorrectiveMinor!$R10,Gen_Vessels!$C$3:$C$500,0),1)),"")
A11: =IF(ISBLANK($B11)=FALSE,IF(AND($D11>0,$E11<=0,$F11<=0),_xlfn.CONCAT("ofw_",$B11),IF(AND($D11<=0,$E11>0,$F11<=0),_xlfn.CONCAT("owc_",$B11),IF(AND($D11<=0,$E11<=0,$F11>0),_xlfn.CONCAT("opv_",$B11),_xlfn.CONCAT("oce_",$B11)))),"") | P11: =IFERROR(IF(ISBLANK(O11),"",INDEX(Gen_Vessels!$A$3:$C$500,MATCH(O11,Gen_Vessels!$C$3:$C$500,0),1)),"") | S11: =IFERROR(IF(ISBLANK(R11),"",INDEX(Gen_Vessels!$A$3:$C$500,MATCH(CorrectiveMinor!$R11,Gen_Vessels!$C$3:$C$500,0),1)),"")
A12: =IF(ISBLANK($B12)=FALSE,IF(AND($D12>0,$E12<=0,$F12<=0),_xlfn.CONCAT("ofw_",$B12),IF(AND($D12<=0,$E12>0,$F12<=0),_xlfn.CONCAT("owc_",$B12),IF(AND($D12<=0,$E12<=0,$F12>0),_xlfn.CONCAT("opv_",$B12),_xlfn.CONCAT("oce_",$B12)))),"") | P12: =IFERROR(IF(ISBLANK(O12),"",INDEX(Gen_Vessels!$A$3:$C$500,MATCH(O12,Gen_Vessels!$C$3:$C$500,0),1)),"") | S12: =IFERROR(IF(ISBLANK(R12),"",INDEX(Gen_Vessels!$A$3:$C$500,MATCH(CorrectiveMinor!$R12,Gen_Vessels!$C$3:$C$500,0),1)),"")
A13: =IF(ISBLANK($B13)=FALSE,IF(AND($D13>0,$E13<=0,$F13<=0),_xlfn.CONCAT("ofw_",$B13),IF(AND($D13<=0,$E13>0,$F13<=0),_xlfn.CONCAT("owc_",$B13),IF(AND($D13<=0,$E13<=0,$F13>0),_xlfn.CONCAT("opv_",$B13),_xlfn.CONCAT("oce_",$B13)))),"") | P13: =IFERROR(IF(ISBLANK(O13),"",INDEX(Gen_Vessels!$A$3:$C$500,MATCH(O13,Gen_Vessels!$C$3:$C$500,0),1)),"") | S13: =IFERROR(IF(ISBLANK(R13),"",INDEX(Gen_Vessels!$A$3:$C$500,MATCH(CorrectiveMinor!$R13,Gen_Vessels!$C$3:$C$500,0),1)),"")
A14: =IF(ISBLANK($B14)=FALSE,IF(AND($D14>0,$E14<=0,$F14<=0),_xlfn.CONCAT("ofw_",$B14),IF(AND($D14<=0,$E14>0,$F14<=0),_xlfn.CONCAT("owc_",$B14),IF(AND($D14<=0,$E14<=0,$F14>0),_xlfn.CONCAT("opv_",$B14),_xlfn.CONCAT("oce_",$B14)))),"") | P14: =IFERROR(IF(ISBLANK(O14),"",INDEX(Gen_Vessels!$A$3:$C$500,MATCH(O14,Gen_Vessels!$C$3:$C$500,0),1)),"") | S14: =IFERROR(IF(ISBLANK(R14),"",INDEX(Gen_Vessels!$A$3:$C$500,MATCH(CorrectiveMinor!$R14,Gen_Vessels!$C$3:$C$500,0),1)),"")
A15: =IF(ISBLANK($B15)=FALSE,IF(AND($D15>0,$E15<=0,$F15<=0),_xlfn.CONCAT("ofw_",$B15),IF(AND($D15<=0,$E15>0,$F15<=0),_xlfn.CONCAT("owc_",$B15),IF(AND($D15<=0,$E15<=0,$F15>0),_xlfn.CONCAT("opv_",$B15),_xlfn.CONCAT("oce_",$B15)))),"") | P15: =IFERROR(IF(ISBLANK(O15),"",INDEX(Gen_Vessels!$A$3:$C$500,MATCH(O15,Gen_Vessels!$C$3:$C$500,0),1)),"") | S15: =IFERROR(IF(ISBLANK(R15),"",INDEX(Gen_Vessels!$A$3:$C$500,MATCH(CorrectiveMinor!$R15,Gen_Vessels!$C$3:$C$500,0),1)),"")
A16: =IF(ISBLANK($B16)=FALSE,IF(AND($D16>0,$E16<=0,$F16<=0),_xlfn.CONCAT("ofw_",$B16),IF(AND($D16<=0,$E16>0,$F16<=0),_xlfn.CONCAT("owc_",$B16),IF(AND($D16<=0,$E16<=0,$F16>0),_xlfn.CONCAT("opv_",$B16),_xlfn.CONCAT("oce_",$B16)))),"") | P16: =IFERROR(IF(ISBLANK(O16),"",INDEX(Gen_Vessels!$A$3:$C$500,MATCH(O16,Gen_Vessels!$C$3:$C$500,0),1)),"") | S16: =IFERROR(IF(ISBLANK(R16),"",INDEX(Gen_Vessels!$A$3:$C$500,MATCH(CorrectiveMinor!$R16,Gen_Vessels!$C$3:$C$500,0),1)),"")
A17: =IF(ISBLANK($B17)=FALSE,IF(AND($D17>0,$E17<=0,$F17<=0),_xlfn.CONCAT("ofw_",$B17),IF(AND($D17<=0,$E17>0,$F17<=0),_xlfn.CONCAT("owc_",$B17),IF(AND($D17<=0,$E17<=0,$F17>0),_xlfn.CONCAT("opv_",$B17),_xlfn.CONCAT("oce_",$B17)))),"") | P17: =IFERROR(IF(ISBLANK(O17),"",INDEX(Gen_Vessels!$A$3:$C$500,MATCH(O17,Gen_Vessels!$C$3:$C$500,0),1)),"") | S17: =IFERROR(IF(ISBLANK(R17),"",INDEX(Gen_Vessels!$A$3:$C$500,MATCH(CorrectiveMinor!$R17,Gen_Vessels!$C$3:$C$500,0),1)),"")
... A484: =IF(ISBLANK($B484)=FALSE,IF(AND($D484>0,$E484<=0,$F484<=0),_xlfn.CONCAT("ofw_",$B484),IF(AND($D484<=0,$E484>0,$F484<=0),_xlfn.CONCAT("owc_",$B484),IF(AND($D484<=0,$E484<=0,$F484>0),_xlfn.CONCAT("opv_",$B484),_xlfn.CONCAT("oce_",$B484)))),"") | P484: =IFERROR(IF(ISBLANK(O484),"",INDEX(Gen_Vessels!$A$3:$C$500,MATCH(O484,Gen_Vessels!$C$3:$C$500,0),1)),"") | S484: =IFERROR(IF(ISBLANK(R484),"",INDEX(Gen_Vessels!$A$3:$C$500,MATCH(CorrectiveMinor!$R484,Gen_Vessels!$C$3:$C$500,0),1)),"")
P485: =IFERROR(IF(ISBLANK(O485),"",INDEX(Gen_Vessels!$A$3:$C$500,MATCH(O485,Gen_Vessels!$C$3:$C$500,0),1)),"") | S485: =IFERROR(IF(ISBLANK(R485),"",INDEX(Gen_Vessels!$A$3:$C$500,MATCH(CorrectiveMinor!$R485,Gen_Vessels!$C$3:$C$500,0),1)),"")
P486: =IFERROR(IF(ISBLANK(O486),"",INDEX(Gen_Vessels!$A$3:$C$500,MATCH(O486,Gen_Vessels!$C$3:$C$500,0),1)),"") | S486: =IFERROR(IF(ISBLANK(R486),"",INDEX(Gen_Vessels!$A$3:$C$500,MATCH(CorrectiveMinor!$R486,Gen_Vessels!$C$3:$C$500,0),1)),"")
P487: =IFERROR(IF(ISBLANK(O487),"",INDEX(Gen_Vessels!$A$3:$C$500,MATCH(O487,Gen_Vessels!$C$3:$C$500,0),1)),"") | S487: =IFERROR(IF(ISBLANK(R487),"",INDEX(Gen_Vessels!$A$3:$C$500,MATCH(CorrectiveMinor!$R487,Gen_Vessels!$C$3:$C$500,0),1)),"")
P488: =IFERROR(IF(ISBLANK(O488),"",INDEX(Gen_Vessels!$A$3:$C$500,MATCH(O488,Gen_Vessels!$C$3:$C$500,0),1)),"") | S488: =IFERROR(IF(ISBLANK(R488),"",INDEX(Gen_Vessels!$A$3:$C$500,MATCH(CorrectiveMinor!$R488,Gen_Vessels!$C$3:$C$500,0),1)),"")
P489: =IFERROR(IF(ISBLANK(O489),"",INDEX(Gen_Vessels!$A$3:$C$500,MATCH(O489,Gen_Vessels!$C$3:$C$500,0),1)),"") | S489: =IFERROR(IF(ISBLANK(R489),"",INDEX(Gen_Vessels!$A$3:$C$500,MATCH(CorrectiveMinor!$R489,Gen_Vessels!$C$3:$C$500,0),1)),"")
P490: =IFERROR(IF(ISBLANK(O490),"",INDEX(Gen_Vessels!$A$3:$C$500,MATCH(O490,Gen_Vessels!$C$3:$C$500,0),1)),"") | S490: =IFERROR(IF(ISBLANK(R490),"",INDEX(Gen_Vessels!$A$3:$C$500,MATCH(CorrectiveMinor!$R490,Gen_Vessels!$C$3:$C$500,0),1)),"")
P491: =IFERROR(IF(ISBLANK(O491),"",INDEX(Gen_Vessels!$A$3:$C$500,MATCH(O491,Gen_Vessels!$C$3:$C$500,0),1)),"") | S491: =IFERROR(IF(ISBLANK(R491),"",INDEX(Gen_Vessels!$A$3:$C$500,MATCH(CorrectiveMinor!$R491,Gen_Vessels!$C$3:$C$500,0),1)),"")
P492: =IFERROR(IF(ISBLANK(O492),"",INDEX(Gen_Vessels!$A$3:$C$500,MATCH(O492,Gen_Vessels!$C$3:$C$500,0),1)),"") | S492: =IFERROR(IF(ISBLANK(R492),"",INDEX(Gen_Vessels!$A$3:$C$500,MATCH(CorrectiveMinor!$R492,Gen_Vessels!$C$3:$C$500,0),1)),"")

Sheet CorrectiveMajor
A1: id | B1: id_short | C1: name | D1: tow_to_port | E1: vessel1 | F1: vessel1_id | G1: vessel1_qt | H1: vessel2 | I1: vessel2_id | J1: vessel2_qt | K1: rov_drone | L1: technicians_required | M1: technician_cost | N1: parts_cost | O1: other_costs | P1: port_costs
A2: - | B2: - | C2: - | D2: - | E2: - | F2: - | G2: - | H2: - | I2: - | J2: - | K2: - | L2: - | M2: €/technician/day | N2: € | O2: € | P2: €/day
A3: =IF(ISBLANK($B3)=FALSE,_xlfn.CONCAT("owc_",$B3),"") -> owc_MJ1 | B3: MJ1 | C3: Power Electronics | D3: FALSE | E3: V002 - Multicat | F3: =IFERROR(IF(ISBLANK(E3),"",INDEX(Gen_Vessels!$A$3:$C$500,MATCH(E3,Gen_Vessels!$C$3:$C$500,0),1)),"") -> V002 | G3: 1 | I3: =IFERROR(IF(ISBLANK(H3),"",INDEX([1]Gen_Vessels!$A$6:$C$503,MATCH(H3,[1]Gen_Vessels!$C$6:$C$503,0),1)),"") | J3: 1 | L3: 3 | M3: 0 | N3: 0
A4: =IF(ISBLANK($B4)=FALSE,_xlfn.CONCAT("owc_",$B4),"") -> owc_MJ2 | B4: MJ2 | C4: C-Gen | D4: TRUE | F4: =IFERROR(IF(ISBLANK(E4),"",INDEX(Gen_Vessels!$A$3:$C$500,MATCH(E4,Gen_Vessels!$C$3:$C$500,0),1)),"") | G4: 1 | I4: =IFERROR(IF(ISBLANK(H4),"",INDEX([1]Gen_Vessels!$A$6:$C$503,MATCH(H4,[1]Gen_Vessels!$C$6:$C$503,0),1)),"") | J4: 1 | L4: 3 | M4: 0 | N4: 0
A5: =IF(ISBLANK($B5)=FALSE,_xlfn.CONCAT("owc_",$B5),"") -> owc_MJ3 | B5: MJ3 | C5: PTO | D5: TRUE | F5: =IFERROR(IF(ISBLANK(E5),"",INDEX(Gen_Vessels!$A$3:$C$500,MATCH(E5,Gen_Vessels!$C$3:$C$500,0),1)),"") | G5: 1 | I5: =IFERROR(IF(ISBLANK(H5),"",INDEX([1]Gen_Vessels!$A$6:$C$503,MATCH(H5,[1]Gen_Vessels!$C$6:$C$503,0),1)),"") | J5: 1 | L5: 3 | M5: 0 | N5: 0
A6: =IF(ISBLANK($B6)=FALSE,_xlfn.CONCAT("owc_",$B6),"") | F6: =IFERROR(IF(ISBLANK(E6),"",INDEX(Gen_Vessels!$A$3:$C$500,MATCH(E6,Gen_Vessels!$C$3:$C$500,0),1)),"") | I6: =IFERROR(IF(ISBLANK(H6),"",INDEX(Gen_Vessels!$A$3:$C$500,MATCH(H6,Gen_Vessels!$C$3:$C$500,0),1)),"")
A7: =IF(ISBLANK($B7)=FALSE,_xlfn.CONCAT("owc_",$B7),"") | F7: =IFERROR(IF(ISBLANK(E7),"",INDEX(Gen_Vessels!$A$3:$C$500,MATCH(E7,Gen_Vessels!$C$3:$C$500,0),1)),"") | I7: =IFERROR(IF(ISBLANK(H7),"",INDEX(Gen_Vessels!$A$3:$C$500,MATCH(H7,Gen_Vessels!$C$3:$C$500,0),1)),"")
A8: =IF(ISBLANK($B8)=FALSE,_xlfn.CONCAT("owc_",$B8),"") | F8: =IFERROR(IF(ISBLANK(E8),"",INDEX(Gen_Vessels!$A$3:$C$500,MATCH(E8,Gen_Vessels!$C$3:$C$500,0),1)),"") | I8: =IFERROR(IF(ISBLANK(H8),"",INDEX(Gen_Vessels!$A$3:$C$500,MATCH(H8,Gen_Vessels!$C$3:$C$500,0),1)),"")
A9: =IF(ISBLANK($B9)=FALSE,_xlfn.CONCAT("owc_",$B9),"") | F9: =IFERROR(IF(ISBLANK(E9),"",INDEX(Gen_Vessels!$A$3:$C$500,MATCH(E9,Gen_Vessels!$C$3:$C$500,0),1)),"") | I9: =IFERROR(IF(ISBLANK(H9),"",INDEX(Gen_Vessels!$A$3:$C$500,MATCH(H9,Gen_Vessels!$C$3:$C$500,0),1)),"")
A10: =IF(ISBLANK($B10)=FALSE,_xlfn.CONCAT("owc_",$B10),"") | F10: =IFERROR(IF(ISBLANK(E10),"",INDEX(Gen_Vessels!$A$3:$C$500,MATCH(E10,Gen_Vessels!$C$3:$C$500,0),1)),"") | I10: =IFERROR(IF(ISBLANK(H10),"",INDEX(Gen_Vessels!$A$3:$C$500,MATCH(H10,Gen_Vessels!$C$3:$C$500,0),1)),"")
A11: =IF(ISBLANK($B11)=FALSE,_xlfn.CONCAT("owc_",$B11),"") | F11: =IFERROR(IF(ISBLANK(E11),"",INDEX(Gen_Vessels!$A$3:$C$500,MATCH(E11,Gen_Vessels!$C$3:$C$500,0),1)),"") | I11: =IFERROR(IF(ISBLANK(H11),"",INDEX(Gen_Vessels!$A$3:$C$500,MATCH(H11,Gen_Vessels!$C$3:$C$500,0),1)),"")
A12: =IF(ISBLANK($B12)=FALSE,_xlfn.CONCAT("owc_",$B12),"") | F12: =IFERROR(IF(ISBLANK(E12),"",INDEX(Gen_Vessels!$A$3:$C$500,MATCH(E12,Gen_Vessels!$C$3:$C$500,0),1)),"") | I12: =IFERROR(IF(ISBLANK(H12),"",INDEX(Gen_Vessels!$A$3:$C$500,MATCH(H12,Gen_Vessels!$C$3:$C$500,0),1)),"")
A13: =IF(ISBLANK($B13)=FALSE,_xlfn.CONCAT("owc_",$B13),"") | F13: =IFERROR(IF(ISBLANK(E13),"",INDEX(Gen_Vessels!$A$3:$C$500,MATCH(E13,Gen_Vessels!$C$3:$C$500,0),1)),"") | I13: =IFERROR(IF(ISBLANK(H13),"",INDEX(Gen_Vessels!$A$3:$C$500,MATCH(H13,Gen_Vessels!$C$3:$C$500,0),1)),"")
A14: =IF(ISBLANK($B14)=FALSE,_xlfn.CONCAT("owc_",$B14),"") | F14: =IFERROR(IF(ISBLANK(E14),"",INDEX(Gen_Vessels!$A$3:$C$500,MATCH(E14,Gen_Vessels!$C$3:$C$500,0),1)),"") | I14: =IFERROR(IF(ISBLANK(H14),"",INDEX(Gen_Vessels!$A$3:$C$500,MATCH(H14,Gen_Vessels!$C$3:$C$500,0),1)),"")
A15: =IF(ISBLANK($B15)=FALSE,_xlfn.CONCAT("owc_",$B15),"") | F15: =IFERROR(IF(ISBLANK(E15),"",INDEX(Gen_Vessels!$A$3:$C$500,MATCH(E15,Gen_Vessels!$C$3:$C$500,0),1)),"") | I15: =IFERROR(IF(ISBLANK(H15),"",INDEX(Gen_Vessels!$A$3:$C$500,MATCH(H15,Gen_Vessels!$C$3:$C$500,0),1)),"")
A16: =IF(ISBLANK($B16)=FALSE,_xlfn.CONCAT("owc_",$B16),"") | F16: =IFERROR(IF(ISBLANK(E16),"",INDEX(Gen_Vessels!$A$3:$C$500,MATCH(E16,Gen_Vessels!$C$3:$C$500,0),1)),"") | I16: =IFERROR(IF(ISBLANK(H16),"",INDEX(Gen_Vessels!$A$3:$C$500,MATCH(H16,Gen_Vessels!$C$3:$C$500,0),1)),"")
A17: =IF(ISBLANK($B17)=FALSE,_xlfn.CONCAT("owc_",$B17),"") | F17: =IFERROR(IF(ISBLANK(E17),"",INDEX(Gen_Vessels!$A$3:$C$500,MATCH(E17,Gen_Vessels!$C$3:$C$500,0),1)),"") | I17: =IFERROR(IF(ISBLANK(H17),"",INDEX(Gen_Vessels!$A$3:$C$500,MATCH(H17,Gen_Vessels!$C$3:$C$500,0),1)),"")
... A95: =IF(ISBLANK($B95)=FALSE,_xlfn.CONCAT("owc_",$B95),"") | F95: =IFERROR(IF(ISBLANK(E95),"",INDEX(Gen_Vessels!$A$3:$C$500,MATCH(E95,Gen_Vessels!$C$3:$C$500,0),1)),"") | I95: =IFERROR(IF(ISBLANK(H95),"",INDEX(Gen_Vessels!$A$3:$C$500,MATCH(H95,Gen_Vessels!$C$3:$C$500,0),1)),"")
F96: =IFERROR(IF(ISBLANK(E96),"",INDEX(Gen_Vessels!$A$3:$C$500,MATCH(E96,Gen_Vessels!$C$3:$C$500,0),1)),"") | I96: =IFERROR(IF(ISBLANK(H96),"",INDEX(Gen_Vessels!$A$3:$C$500,MATCH(H96,Gen_Vessels!$C$3:$C$500,0),1)),"")
F97: =IFERROR(IF(ISBLANK(E97),"",INDEX(Gen_Vessels!$A$3:$C$500,MATCH(E97,Gen_Vessels!$C$3:$C$500,0),1)),"") | I97: =IFERROR(IF(ISBLANK(H97),"",INDEX(Gen_Vessels!$A$3:$C$500,MATCH(H97,Gen_Vessels!$C$3:$C$500,0),1)),"")
F98: =IFERROR(IF(ISBLANK(E98),"",INDEX(Gen_Vessels!$A$3:$C$500,MATCH(E98,Gen_Vessels!$C$3:$C$500,0),1)),"") | I98: =IFERROR(IF(ISBLANK(H98),"",INDEX(Gen_Vessels!$A$3:$C$500,MATCH(H98,Gen_Vessels!$C$3:$C$500,0),1)),"")
F99: =IFERROR(IF(ISBLANK(E99),"",INDEX(Gen_Vessels!$A$3:$C$500,MATCH(E99,Gen_Vessels!$C$3:$C$500,0),1)),"") | I99: =IFERROR(IF(ISBLANK(H99),"",INDEX(Gen_Vessels!$A$3:$C$500,MATCH(H99,Gen_Vessels!$C$3:$C$500,0),1)),"")
F100: =IFERROR(IF(ISBLANK(E100),"",INDEX(Gen_Vessels!$A$3:$C$500,MATCH(E100,Gen_Vessels!$C$3:$C$500,0),1)),"") | I100: =IFERROR(IF(ISBLANK(H100),"",INDEX(Gen_Vessels!$A$3:$C$500,MATCH(H100,Gen_Vessels!$C$3:$C$500,0),1)),"")
F101: =IFERROR(IF(ISBLANK(E101),"",INDEX(Gen_Vessels!$A$3:$C$500,MATCH(E101,Gen_Vessels!$C$3:$C$500,0),1)),"") | I101: =IFERROR(IF(ISBLANK(H101),"",INDEX(Gen_Vessels!$A$3:$C$500,MATCH(H101,Gen_Vessels!$C$3:$C$500,0),1)),"")
F102: =IFERROR(IF(ISBLANK(E102),"",INDEX(Gen_Vessels!$A$3:$C$500,MATCH(E102,Gen_Vessels!$C$3:$C$500,0),1)),"") | I102: =IFERROR(IF(ISBLANK(H102),"",INDEX(Gen_Vessels!$A$3:$C$500,MATCH(H102,Gen_Vessels!$C$3:$C$500,0),1)),"")
F103: =IFERROR(IF(ISBLANK(E103),"",INDEX(Gen_Vessels!$A$3:$C$500,MATCH(E103,Gen_Vessels!$C$3:$C$500,0),1)),"") | I103: =IFERROR(IF(ISBLANK(H103),"",INDEX(Gen_Vessels!$A$3:$C$500,MATCH(H103,Gen_Vessels!$C$3:$C$500,0),1)),"")
F104: =IFERROR(IF(ISBLANK(E104),"",INDEX(Gen_Vessels!$A$3:$C$500,MATCH(E104,Gen_Vessels!$C$3:$C$500,0),1)),"") | I104: =IFERROR(IF(ISBLANK(H104),"",INDEX(Gen_Vessels!$A$3:$C$500,MATCH(H104,Gen_Vessels!$C$3:$C$500,0),1)),"")
F105: =IFERROR(IF(ISBLANK(E105),"",INDEX(Gen_Vessels!$A$3:$C$500,MATCH(E105,Gen_Vessels!$C$3:$C$500,0),1)),"") | I105: =IFERROR(IF(ISBLANK(H105),"",INDEX(Gen_Vessels!$A$3:$C$500,MATCH(H105,Gen_Vessels!$C$3:$C$500,0),1)),"")
F106: =IFERROR(IF(ISBLANK(E106),"",INDEX(Gen_Vessels!$A$3:$C$500,MATCH(E106,Gen_Vessels!$C$3:$C$500,0),1)),"") | I106: =IFERROR(IF(ISBLANK(H106),"",INDEX(Gen_Vessels!$A$3:$C$500,MATCH(H106,Gen_Vessels!$C$3:$C$500,0),1)),"")
F107: =IFERROR(IF(ISBLANK(E107),"",INDEX(Gen_Vessels!$A$3:$C$500,MATCH(E107,Gen_Vessels!$C$3:$C$500,0),1)),"") | I107: =IFERROR(IF(ISBLANK(H107),"",INDEX(Gen_Vessels!$A$3:$C$500,MATCH(H107,Gen_Vessels!$C$3:$C$500,0),1)),"")
... F498: =IFERROR(IF(ISBLANK(E498),"",INDEX(Gen_Vessels!$A$3:$C$500,MATCH(E498,Gen_Vessels!$C$3:$C$500,0),1)),"") | I498: =IFERROR(IF(ISBLANK(H498),"",INDEX(Gen_Vessels!$A$3:$C$500,MATCH(H498,Gen_Vessels!$C$3:$C$500,0),1)),"")

Sheet OperationTow
A1: id | B1: id_short | C1: name | D1: vessel1 | E1: vessel1_id | F1: vessel1_qt | G1: vessel2 | H1: vessel2_id | I1: vessel2_qt | J1: additional_previous_op_tow | K1: string_disconnection | L1: recommissioning_time | M1: rov_drone | N1: technicians_required | O1: technician_cost | P1: other_costs
A2: - | B2: - | C2: - | D2: - | E2: - | F2: - | G2: - | H2: - | I2: - | J2: - | K2: - | L2: hours | M2: - | N2: - | O2: €/technician/day | P2: €
A3: =IF(ISBLANK($B3)=FALSE,_xlfn.CONCAT($B3,"_tow"),"") -> owc_removal_tow | B3: owc_removal | C3: WEC removal | D3: V002 - Multicat | E3: =IFERROR(IF(ISBLANK(D3),"",INDEX(Gen_Vessels!$A$3:$C$500,MATCH(D3,Gen_Vessels!$C$3:$C$500,0),1)),"") -> V002 | F3: 1 | H3: =IFERROR(IF(ISBLANK(G3),"",INDEX(Gen_Vessels!$A$3:$C$500,MATCH(G3,Gen_Vessels!$C$3:$C$500,0),1)),"") | I3: 1 | N3: 1 | O3: 0
A4: =IF(ISBLANK($B4)=FALSE,_xlfn.CONCAT($B4,"_tow"),"") -> owc_redeploy_removal_tow | B4: owc_redeploy_removal | C4: WEC re-deploy and removal | D4: V002 - Multicat | E4: =IFERROR(IF(ISBLANK(D4),"",INDEX(Gen_Vessels!$A$3:$C$500,MATCH(D4,Gen_Vessels!$C$3:$C$500,0),1)),"") -> V002 | F4: 1 | H4: =IFERROR(IF(ISBLANK(G4),"",INDEX(Gen_Vessels!$A$3:$C$500,MATCH(G4,Gen_Vessels!$C$3:$C$500,0),1)),"") | I4: 1 | N4: 1 | O4: 0
A5: =IF(ISBLANK($B5)=FALSE,_xlfn.CONCAT($B5,"_tow"),"") -> owc_redeploy_tow | B5: owc_redeploy | C5: WEC re-deploy | D5: V002 - Multicat | E5: =IFERROR(IF(ISBLANK(D5),"",INDEX(Gen_Vessels!$A$3:$C$500,MATCH(D5,Gen_Vessels!$C$3:$C$500,0),1)),"") -> V002 | F5: 1 | H5: =IFERROR(IF(ISBLANK(G5),"",INDEX(Gen_Vessels!$A$3:$C$500,MATCH(G5,Gen_Vessels!$C$3:$C$500,0),1)),"") | I5: 1 | N5: 1 | O5: 0
A6: =IF(ISBLANK($B6)=FALSE,_xlfn.CONCAT($B6,"_tow"),"") | E6: =IFERROR(IF(ISBLANK(D6),"",INDEX(Gen_Vessels!$A$3:$C$500,MATCH(D6,Gen_Vessels!$C$3:$C$500,0),1)),"") | H6: =IFERROR(IF(ISBLANK(G6),"",INDEX(Gen_Vessels!$A$3:$C$500,MATCH(G6,Gen_Vessels!$C$3:$C$500,0),1)),"")
A7: =IF(ISBLANK($B7)=FALSE,_xlfn.CONCAT($B7,"_tow"),"") | E7: =IFERROR(IF(ISBLANK(D7),"",INDEX(Gen_Vessels!$A$3:$C$500,MATCH(D7,Gen_Vessels!$C$3:$C$500,0),1)),"") | H7: =IFERROR(IF(ISBLANK(G7),"",INDEX(Gen_Vessels!$A$3:$C$500,MATCH(G7,Gen_Vessels!$C$3:$C$500,0),1)),"")
A8: =IF(ISBLANK($B8)=FALSE,_xlfn.CONCAT($B8,"_tow"),"") | E8: =IFERROR(IF(ISBLANK(D8),"",INDEX(Gen_Vessels!$A$3:$C$500,MATCH(D8,Gen_Vessels!$C$3:$C$500,0),1)),"") | H8: =IFERROR(IF(ISBLANK(G8),"",INDEX(Gen_Vessels!$A$3:$C$500,MATCH(G8,Gen_Vessels!$C$3:$C$500,0),1)),"")
A9: =IF(ISBLANK($B9)=FALSE,_xlfn.CONCAT($B9,"_tow"),"") | E9: =IFERROR(IF(ISBLANK(D9),"",INDEX(Gen_Vessels!$A$3:$C$500,MATCH(D9,Gen_Vessels!$C$3:$C$500,0),1)),"") | H9: =IFERROR(IF(ISBLANK(G9),"",INDEX(Gen_Vessels!$A$3:$C$500,MATCH(G9,Gen_Vessels!$C$3:$C$500,0),1)),"")
A10: =IF(ISBLANK($B10)=FALSE,_xlfn.CONCAT($B10,"_tow"),"") | E10: =IFERROR(IF(ISBLANK(D10),"",INDEX(Gen_Vessels!$A$3:$C$500,MATCH(D10,Gen_Vessels!$C$3:$C$500,0),1)),"") | H10: =IFERROR(IF(ISBLANK(G10),"",INDEX(Gen_Vessels!$A$3:$C$500,MATCH(G10,Gen_Vessels!$C$3:$C$500,0),1)),"")
A11: =IF(ISBLANK($B11)=FALSE,_xlfn.CONCAT($B11,"_tow"),"") | E11: =IFERROR(IF(ISBLANK(D11),"",INDEX(Gen_Vessels!$A$3:$C$500,MATCH(D11,Gen_Vessels!$C$3:$C$500,0),1)),"") | H11: =IFERROR(IF(ISBLANK(G11),"",INDEX(Gen_Vessels!$A$3:$C$500,MATCH(G11,Gen_Vessels!$C$3:$C$500,0),1)),"")
A12: =IF(ISBLANK($B12)=FALSE,_xlfn.CONCAT($B12,"_tow"),"") | E12: =IFERROR(IF(ISBLANK(D12),"",INDEX(Gen_Vessels!$A$3:$C$500,MATCH(D12,Gen_Vessels!$C$3:$C$500,0),1)),"") | H12: =IFERROR(IF(ISBLANK(G12),"",INDEX(Gen_Vessels!$A$3:$C$500,MATCH(G12,Gen_Vessels!$C$3:$C$500,0),1)),"")
A13: =IF(ISBLANK($B13)=FALSE,_xlfn.CONCAT($B13,"_tow"),"") | E13: =IFERROR(IF(ISBLANK(D13),"",INDEX(Gen_Vessels!$A$3:$C$500,MATCH(D13,Gen_Vessels!$C$3:$C$500,0),1)),"") | H13: =IFERROR(IF(ISBLANK(G13),"",INDEX(Gen_Vessels!$A$3:$C$500,MATCH(G13,Gen_Vessels!$C$3:$C$500,0),1)),"")
A14: =IF(ISBLANK($B14)=FALSE,_xlfn.CONCAT($B14,"_tow"),"") | E14: =IFERROR(IF(ISBLANK(D14),"",INDEX(Gen_Vessels!$A$3:$C$500,MATCH(D14,Gen_Vessels!$C$3:$C$500,0),1)),"") | H14: =IFERROR(IF(ISBLANK(G14),"",INDEX(Gen_Vessels!$A$3:$C$500,MATCH(G14,Gen_Vessels!$C$3:$C$500,0),1)),"")
A15: =IF(ISBLANK($B15)=FALSE,_xlfn.CONCAT($B15,"_tow"),"") | E15: =IFERROR(IF(ISBLANK(D15),"",INDEX(Gen_Vessels!$A$3:$C$500,MATCH(D15,Gen_Vessels!$C$3:$C$500,0),1)),"") | H15: =IFERROR(IF(ISBLANK(G15),"",INDEX(Gen_Vessels!$A$3:$C$500,MATCH(G15,Gen_Vessels!$C$3:$C$500,0),1)),"")
A16: =IF(ISBLANK($B16)=FALSE,_xlfn.CONCAT($B16,"_tow"),"") | E16: =IFERROR(IF(ISBLANK(D16),"",INDEX(Gen_Vessels!$A$3:$C$500,MATCH(D16,Gen_Vessels!$C$3:$C$500,0),1)),"") | H16: =IFERROR(IF(ISBLANK(G16),"",INDEX(Gen_Vessels!$A$3:$C$500,MATCH(G16,Gen_Vessels!$C$3:$C$500,0),1)),"")
A17: =IF(ISBLANK($B17)=FALSE,_xlfn.CONCAT($B17,"_tow"),"") | E17: =IFERROR(IF(ISBLANK(D17),"",INDEX(Gen_Vessels!$A$3:$C$500,MATCH(D17,Gen_Vessels!$C$3:$C$500,0),1)),"") | H17: =IFERROR(IF(ISBLANK(G17),"",INDEX(Gen_Vessels!$A$3:$C$500,MATCH(G17,Gen_Vessels!$C$3:$C$500,0),1)),"")
... A500: =IF(ISBLANK($B500)=FALSE,_xlfn.CONCAT($B500,"_tow"),"") | E500: =IFERROR(IF(ISBLANK(D500),"",INDEX(Gen_Vessels!$A$3:$C$500,MATCH(D500,Gen_Vessels!$C$3:$C$500,0),1)),"") | H500: =IFERROR(IF(ISBLANK(G500),"",INDEX(Gen_Vessels!$A$3:$C$500,MATCH(G500,Gen_Vessels!$C$3:$C$500,0),1)),"")

Sheet Activities
A1: id | B1: op_type | C1: op | D1: name | E1: location | F1: wtg_shutdown_dur | G1: wec_shutdown_dur | H1: pv_shutdown_dur | I1: duration | J1: hs | K1: tp | L1: ws | M1: ws_hub | N1: cs | O1: light
A2: - | B2: - | C2: - | D2: - | F2: - | G2: - | H2: - | I2: hours | J2: m | K2: s | L2: m/s | M2: m/s | N2: m/s | O2: -
A3: CPO_A30_A1 | B3: Tow | C3: owc_removal_tow | D3: Transit to site | E3: transit | J3: 1.5 | O3: FALSE
A4: CPO_A30_A2 | B4: Tow | C4: owc_removal_tow | D4: WEC disconnect | E4: site | G4: TRUE | I4: 2 | J4: 1.5 | O4: TRUE
A5: CPO_A30_A3 | B5: Tow | C5: owc_removal_tow | D5: Tow to port | E5: transit | G5: TRUE | J5: 1.5 | O5: FALSE
A6: CPO_A31_A1 | B6: Tow | C6: owc_redeploy_removal_tow | D6: Tow to site | E6: transit | G6: TRUE | J6: 1.5 | O6: FALSE
A7: CPO_A31_A2 | B7: Tow | C7: owc_redeploy_removal_tow | D7: WEC connect | E7: site | G7: TRUE | I7: 2 | J7: 1.5 | O7: TRUE
A8: CPO_A31_A3 | B8: Tow | C8: owc_redeploy_removal_tow | D8: Transit to next device | E8: site | J8: 1.5 | O8: FALSE
A9: CPO_A31_A4 | B9: Tow | C9: owc_redeploy_removal_tow | D9: WEC disconnect | E9: site | G9: TRUE | I9: 2 | J9: 1.5 | O9: TRUE
A10: CPO_A31_A5 | B10: Tow | C10: owc_redeploy_removal_tow | D10: Tow to port | E10: transit | G10: TRUE | J10: 1.5 | O10: FALSE
A11: CPO_A33_A1 | B11: Tow | C11: owc_redeploy_tow | D11: Tow to site | E11: transit | G11: TRUE | J11: 1.5 | O11: FALSE
A12: CPO_A33_A2 | B12: Tow | C12: owc_redeploy_tow | D12: WEC connect | E12: site | G12: TRUE | I12: 2 | J12: 1.5 | O12: TRUE
A13: CPO_A33_A3 | B13: Tow | C13: owc_redeploy_tow | D13: Transit to port | E13: transit | J13: 1.5 | O13: FALSE
A14: ACT_MJ2_01 | B14: CorrectiveMajor | C14: owc_MJ2 | D14: Maintenance G-GEN | E14: port | G14: TRUE | I14: 168 | O14: FALSE
A15: ACT_MJ1_01 | B15: CorrectiveMajor | C15: =IF(ISBLANK($C15)=FALSE,_xlfn.CONCAT("owc_",$C15),"") -> owc_MJ1 | D15: Transit to site | E15: transit | O15: FALSE
A16: ACT_MJ1_02 | B16: CorrectiveMajor | C16: =IF(ISBLANK($C16)=FALSE,_xlfn.CONCAT("owc_",$C16),"") -> owc_MJ1 | D16: Exchange of power electronics | E16: site | G16: TRUE | I16: 6 | J16: 1.5 | O16: TRUE
A17: ACT_MJ1_03 | B17: CorrectiveMajor | C17: =IF(ISBLANK($C17)=FALSE,_xlfn.CONCAT("owc_",$C17),"") -> owc_MJ1 | D17: Transit to port | E17: transit | O17: FALSE
A18: ACT_MJ3_01 | B18: CorrectiveMajor | C18: owc_MJ3 | D18: Maintenance PTO | E18: port | G18: TRUE | I18: 168 | O18: FALSE

Sheet TSA_inputs
A1: input | B1: units | C1: value
A2: Site latitude | B2: degree | C2: 54.037
A3: Site longitude | B3: degree | C3: 5.965
A4: Metocean file location | B4: - | C4: .\tests\test_files\metocean\metocean_1year.csv
A5: Metocean wind speed height | B5: m | C5: 10
A6: Surface roughness | B6: m | C6: 0.0002
A7: Distance to port | B7: km | C7: 5
A8: Transit time between devices pv | B8: hours
A9: Transit time between devices wt | B9: hours
A10: Transit time between devices wec | B10: hours | C10: 0.1
A11: Max WoW between activities | B11: hours | C11: 4
A12: Timeseries analysed percentage (montecarlo) | B12: - | C12: 0.3
A13: Length of export cable | B13: km
A14: Duration of a shift | B14: hours | C14: 12
A15: Failure scenario selection | B15: - | C15: 0
A16: Consider double shifts | B16: - | C16: TRUE
A17: Merge operation vessel type | B17: -
A18: Metocean tow file number | B18: - | C18: 2
A19: Metocean tow file location 1 | B19: - | C19: .\tests\test_files\metocean\metocean_02years.csv
